Workbook
Name 勘定科目: [1]科目・集計!$B$5:$B$18
Name 改定償却等: #REF!
Name 勘定科目_元帳用: #REF!
Name 減価償却一覧: #REF!
Name 仕訳帳: #REF!
Name 仕訳帳・入力範囲: OFFSET(#REF!,0,0,COUNTA(#REF!),17)
Name 指定なし: #REF!
Name 償却_旧法: #REF!
Name 償却_新法: #REF!
Name 償却資産の名称: OFFSET(#REF!,0,0,MAX(#REF!))
Name 償却資産等の勘定科目: OFFSET(#REF!,0,0,MAX(#REF!))
Name 償却率等表: #REF!
Name 端数処理: #REF!
Name 端数補正: #REF!
Name 摘要文例: OFFSET(#REF!,0,0,MAX(#REF!))

Sheet はじめに
B2: こちらはエクセルの複式簿記用の帳簿テンプレート「エクセルフ（試作版）」です。
B3: 素人ですが、最終的には青色申告特別控除を受けるための会計ソフト並の機能を目指しています。
B5: Youtubeチャンネルはこちら（使い方や知識共有など）
B6: https://www.youtube.com/@aoiro-free
B8: メールはこちら（修正点やより良い関数の提案など）
B9: tooltoyama@gmail.com
B11: トーヤマトール | C11: 2025.2 25
B14: 【各シートの簡単な説明】 | D14: 関数 | E14: データ参照
B15: 勘定科目 | C15: 各勘定科目のコードと科目の分類を示しています。 オレンジ部分に新しい科目を追加できます。（分類を間違えないように注意） | D15: なし | E15: なし
B16: 仕訳帳 | C16: これのオレンジ部分に必要な項目を打ち込めば、他の書類は自動的に生成されます。 一般の会計ソフトと違い、年度初めの元入金も仕訳帳に記入します。 行が足りない場合は、オートフィルで増やしてください。 | D16: あり | E16: 勘定科目
B17: ①青色申告決算書 （損益計算書） | C17: 仕訳帳の入力すれば自動的に生成されます。 確定申告の際にはこの値を参考にしてください。 足りない科目はオレンジ色のマスに追加してください。 ※「各種引当金準備金等」の欄は関数を使用していません。ここの勘定科目を使用する人はご自身でカスタマイズをお願いします。 | D17: あり | E17: 仕訳帳
B18: ②月別売上 | C18: 未完成な部分が多いです。 月ごとの売上や仕入れ学の合計が表示されていれば基本的は問題ありません。 申告時に参考にしてください。 | D18: あり | E18: 仕訳帳
B19: ③減価償却 | C19: 未完成な部分が多いです。 必要な方はご自身でカスタマイズしてください。 | D19: なし | E19: なし
B20: ④貸借対照表 | C20: 水色部分の合計値が期首期末左右でそれぞれ一致していれば問題なく処理できています。 | D20: あり | E20: 仕訳帳
B21: 総勘定元帳 | C21: オレンジ部分に勘定科目を入力すると、その科目の書類が作成されます。 行が足りない場合は、オートフィルで増やしてください。 確定申告後に保存用書類を印刷する時にご使用ください。 | D21: あり | E21: 仕訳帳
B22: 集計確認・分析 | C22: 分析用シートですが、ごちゃごちゃしています。不要なら消してください。 仕訳帳で使った科目で足りないものはオレンジ部分に追加してください。 □で囲まれた部分以外は行の挿入→オートフィルで自動生成できます。 ここの設定はごちゃごちゃしてます。要改善です。 | D22: あり | E22: 仕訳帳
B23: 固定資産台帳 | C23: 資産となるものが事業にある場合記入。まだ作っていません。 | D23: なし | E23: なし
B24: 開業費記録 | C24: 開業前にかかった費用を記録しておくもの | D24: あり | E24: なし
B32: Ver | C32: 修正メモ
B33: 0.2.1 | C33: 勘定科目の事業主借が「資産」になっていたのを負債に直しました
B34: 0.2.1 | C34: ④貸借対照表のH２７の引用元が間違っていたので修正しました。
B35: 0.2.1 | C35: 次年度元入金の計算式を修正し、注意文を入れました。
B36: 0.2.2 | C36: 勘定科目１２３に「開業費」を追加しました。
B37: 0.2.2 | C37: 勘定科目３0に「繰延資産償却」を追加しました。
B38: 0.2.2 | C38: 勘定科目６に「商品」を追加しました。
B39: 0.2.2 | C39: 決算書の①②④シートの関数を仕訳帳シートから直接データ抽出するものに変更しました。
B40: 0.2.2 | C40: 外注工賃
B41: 0.2.3 | C41: 期首元入金の中の売掛金などが複数種類あった場合、合計値を表示できるように変更。それに伴い１月１日の売上金による資産増加は除外するように関数変更。
B42: 0.2.4 | C42: 勘定科目の『工具 器具 備品』の文字間の空白を全角に直しました。
B43: 0.3.0 | C43: 仕訳帳のデザイン変更
... B48: 課題 | C48: 勘定科目の「棚卸資産」の「商品」などの科目を使った再構成
C49: Etaxに読み込ませて申請できるデータ形式の出力
C50: 「各種引当金準備金等」の勘定科目を処理できるようにしたい

Sheet 勘定科目
B1: ※自分で科目を追加した場合は①【損益計算書】シートか④【貸借対照表】シートにも追加すること。分析したい場合は【集計確認・分析】シートにも追加すること
B2: コード | C2: 勘定科目 | D2: 分類
B3: 1 | C3: 売上（収入） | D3: 収益
B4: 2 | C4: 期首商品（製品)棚卸高 | D4: 売上原価
B5: 3 | C5: 仕入金額（製品製造原価） | D5: 売上原価
B6: - | C6: - | D6: -
B7: 5 | C7: 期末商品（製品)棚卸高 | D7: 売上原価
B8: 6 | C8: 商品 | D8: 資産
B9: - | C9: - | D9: -
B10: 8 | C10: 租税公課 | D10: 費用
B11: 9 | C11: 荷造運賃 | D11: 費用
B12: 10 | C12: 水道光熱費 | D12: 費用
B13: 11 | C13: 旅費交通費 | D13: 費用
B14: 12 | C14: 通信費 | D14: 費用
B15: 13 | C15: 広告宣伝費 | D15: 費用
B16: 14 | C16: 接待交際費 | D16: 費用
B17: 15 | C17: 損害保険料 | D17: 費用
B18: 16 | C18: 修繕費 | D18: 費用
B19: 17 | C19: 消耗品費 | D19: 費用
B20: 18 | C20: 減価償却費 | D20: 費用
B21: 19 | C21: 福利厚生費 | D21: 費用
... B26: 24 | C26: 貸倒金 | D26: 費用
B27: 25 | D27: 費用
B28: 26 | D28: 費用
B29: 27 | D29: 費用
B30: 28 | D30: 費用
B31: 29 | D31: 費用
B32: 30 | D32: 費用
B33: 31 | C33: 雑費 | D33: 費用
B34: - | C34: - | D34: -
B35: - | C35: - | D35: -
B36: 34 | C36: 貸倒引当金戻入 | D36: 収益
B37: 35 | D37: 収益
B38: 36 | D38: 収益
B39: - | C39: - | D39: -
B40: 38 | C40: 専従者給与 | D40: 費用
B41: 39 | C41: 貸倒引当金繰入 | D41: 費用
B42: 40 | D42: 費用
B43: 41 | D43: 費用
B44: - | C44: - | D44: -
...

Sheet 仕訳帳
H2: ↓入力不可 | I2: ↓入力不可 | J2: ↓入力不可
B3: 仕訳 番号 | C3: 日付 | D3: 勘定科目 コード(借方) | E3: 借方 金額 | F3: 摘要 | G3: 勘定科目 コード(貸方) | H3: 貸方 金額 | I3: 借方科目 | J3: 貸方科目 | K3: メモ | M3: フリースペース
B4: 1 | H4: =E4 -> 0 | I4: =IFERROR(VLOOKUP(D4,勘定科目!$B$2:$D$124,2,FALSE),"") | J4: =IFERROR(VLOOKUP(G4,勘定科目!$B$2:$D$124,2,FALSE),"")
B5: 2 | H5: =E5 -> 0 | I5: =IFERROR(VLOOKUP(D5,勘定科目!$B$2:$D$124,2,FALSE),"") | J5: =IFERROR(VLOOKUP(G5,勘定科目!$B$2:$D$124,2,FALSE),"")
B6: 3 | H6: =E6 -> 0 | I6: =IFERROR(VLOOKUP(D6,勘定科目!$B$2:$D$124,2,FALSE),"") | J6: =IFERROR(VLOOKUP(G6,勘定科目!$B$2:$D$124,2,FALSE),"")
B7: 4 | H7: =E7 -> 0 | I7: =IFERROR(VLOOKUP(D7,勘定科目!$B$2:$D$124,2,FALSE),"") | J7: =IFERROR(VLOOKUP(G7,勘定科目!$B$2:$D$124,2,FALSE),"")
B8: 5 | H8: =E8 -> 0 | I8: =IFERROR(VLOOKUP(D8,勘定科目!$B$2:$D$124,2,FALSE),"") | J8: =IFERROR(VLOOKUP(G8,勘定科目!$B$2:$D$124,2,FALSE),"")
B9: 6 | H9: =E9 -> 0 | I9: =IFERROR(VLOOKUP(D9,勘定科目!$B$2:$D$124,2,FALSE),"") | J9: =IFERROR(VLOOKUP(G9,勘定科目!$B$2:$D$124,2,FALSE),"")
B10: 7 | H10: =E10 -> 0 | I10: =IFERROR(VLOOKUP(D10,勘定科目!$B$2:$D$124,2,FALSE),"") | J10: =IFERROR(VLOOKUP(G10,勘定科目!$B$2:$D$124,2,FALSE),"")
B11: 8 | H11: =E11 -> 0 | I11: =IFERROR(VLOOKUP(D11,勘定科目!$B$2:$D$124,2,FALSE),"") | J11: =IFERROR(VLOOKUP(G11,勘定科目!$B$2:$D$124,2,FALSE),"")
B12: 9 | H12: =E12 -> 0 | I12: =IFERROR(VLOOKUP(D12,勘定科目!$B$2:$D$124,2,FALSE),"") | J12: =IFERROR(VLOOKUP(G12,勘定科目!$B$2:$D$124,2,FALSE),"")
B13: 10 | H13: =E13 -> 0 | I13: =IFERROR(VLOOKUP(D13,勘定科目!$B$2:$D$124,2,FALSE),"") | J13: =IFERROR(VLOOKUP(G13,勘定科目!$B$2:$D$124,2,FALSE),"")
B14: 11 | H14: =E14 -> 0 | I14: =IFERROR(VLOOKUP(D14,勘定科目!$B$2:$D$124,2,FALSE),"") | J14: =IFERROR(VLOOKUP(G14,勘定科目!$B$2:$D$124,2,FALSE),"")
B15: 12 | H15: =E15 -> 0 | I15: =IFERROR(VLOOKUP(D15,勘定科目!$B$2:$D$124,2,FALSE),"") | J15: =IFERROR(VLOOKUP(G15,勘定科目!$B$2:$D$124,2,FALSE),"")
... B138: 135 | H138: =E138 -> 0 | I138: =IFERROR(VLOOKUP(D138,勘定科目!$B$2:$D$124,2,FALSE),"") | J138: =IFERROR(VLOOKUP(G138,勘定科目!$B$2:$D$124,2,FALSE),"")

Sheet ①青色申告決算書（損益計算書）
C1: 令和 | E1: 年分所得税青色申告決算書（一般用）
F2: 住所 | K2: フリガナ 氏名
F3: 事業所 所在地 | K3: 電話番号
F4: 業種名 | I4: 屋号 | K4: 加入団体名
B5: 令和 年 月 日 | E5: 損 益 計 算 書 （自１月１日 至１２月３１日）
B6: 科 目 | E6: 金 額 (円) | G6: 科 目 | J6: 金 額 (円) | L6: 科 目 | P6: 金 額 (円)
B7: 売上(収入)金額 （雑収入を含む） | D7: ① | E7: =SUMIF(仕訳帳!J:J,"売上（収入）",仕訳帳!E:E)-SUMIF(仕訳帳!I:I,"売上（収入）",仕訳帳!E:E) -> 0 | G7: 経費 | H7: 消耗品費 | I7: ⑰ | J7: =IF(H7="",0,SUMIF(仕訳帳!I:I,H7,仕訳帳!E:E)-SUMIF(仕訳帳!J:J,H7,仕訳帳!E:E)) -> 0 | L7: 各 | M7: 繰 | N7: 貸倒引当金 | O7: ㉞
B8: 売上 | C8: 期首商品(製品) 棚 卸 高 | D8: ② | E8: =IFERROR(INDEX(仕訳帳!H:H,MATCH("期首商品（製品)棚卸高",仕訳帳!I:I,0)),0) -> 0 | H8: 減価償却費 | I8: ⑱ | J8: =IF(H8="",0,SUMIF(仕訳帳!I:I,H8,仕訳帳!E:E)-SUMIF(仕訳帳!J:J,H8,仕訳帳!E:E)) -> 0 | L8: 種 | M8: 戻 | O8: ㉟
B9: 原価 | C9: 仕入金額 （製品製造原価） | D9: ③ | E9: =SUMIF(仕訳帳!I:I,"仕入金額（製品製造原価）",仕訳帳!E:E)-SUMIF(仕訳帳!J:J,"仕入金額（製品製造原価）",仕訳帳!E:E) -> 0 | H9: 福利厚生費 | I9: ⑲ | J9: =IF(H9="",0,SUMIF(仕訳帳!I:I,H9,仕訳帳!E:E)-SUMIF(仕訳帳!J:J,H9,仕訳帳!E:E)) -> 0 | L9: 引 | M9: 額 | O9: ㊱
C10: 小計(②+③) | D10: ④ | E10: =SUM(E8:E9) -> 0 | H10: 給料賃金 | I10: ⑳ | J10: =IF(H10="",0,SUMIF(仕訳帳!I:I,H10,仕訳帳!E:E)-SUMIF(仕訳帳!J:J,H10,仕訳帳!E:E)) -> 0 | L10: 当 | M10: 等 | N10: 計 | O10: ㊲ | P10: =SUM(P7:P9) -> 0
C11: 期末商品(製品) 棚 卸 高 | D11: ⑤ | E11: =IFERROR(INDEX(仕訳帳!H:H,MATCH("期末商品（製品)棚卸高",仕訳帳!J:J,0)),0) -> 0 | H11: 外注工賃 | I11: ㉑ | J11: =IF(H11="",0,SUMIF(仕訳帳!I:I,H11,仕訳帳!E:E)-SUMIF(仕訳帳!J:J,H11,仕訳帳!E:E)) -> 0 | L11: 金 | M11: 繰 | N11: 専従者給与 | O11: ㊳
C12: 差引原価(④－⑤) | D12: ⑥ | E12: =E10-E11 -> 0 | H12: 利子割引料 | I12: ㉒ | J12: =IF(H12="",0,SUMIF(仕訳帳!I:I,H12,仕訳帳!E:E)-SUMIF(仕訳帳!J:J,H12,仕訳帳!E:E)) -> 0 | L12: 準 | M12: 入 | N12: 貸倒引当金 | O12: ㊴
B13: 差引金額 （①－⑥） | D13: ⑦ | E13: =E7-E12 -> 0 | H13: 地代家賃 | I13: ㉓ | J13: =IF(H13="",0,SUMIF(仕訳帳!I:I,H13,仕訳帳!E:E)-SUMIF(仕訳帳!J:J,H13,仕訳帳!E:E)) -> 0 | L13: 備 | M13: 額 | O13: ㊵
B14: 経費 | C14: 租税公課 | D14: ⑧ | E14: =SUMIF(仕訳帳!I:I,C14,仕訳帳!E:E)-SUMIF(仕訳帳!J:J,C14,仕訳帳!E:E) -> 0 | H14: 貸倒金 | I14: ㉔ | J14: =IF(H14="",0,SUMIF(仕訳帳!I:I,H14,仕訳帳!E:E)-SUMIF(仕訳帳!J:J,H14,仕訳帳!E:E)) -> 0 | L14: 金 | M14: 等 | O14: ㊶
C15: 荷造運賃 | D15: ⑨ | E15: =SUMIF(仕訳帳!I:I,C15,仕訳帳!E:E)-SUMIF(仕訳帳!J:J,C15,仕訳帳!E:E) -> 0 | I15: ㉕ | J15: =IF(H15="",0,SUMIF(仕訳帳!I:I,H15,仕訳帳!E:E)-SUMIF(仕訳帳!J:J,H15,仕訳帳!E:E)) -> 0 | L15: 等 | N15: 計 | O15: ㊷ | P15: =SUM(P11:P14) -> 0
C16: 水道光熱費 | D16: ⑩ | E16: =SUMIF(仕訳帳!I:I,C16,仕訳帳!E:E)-SUMIF(仕訳帳!J:J,C16,仕訳帳!E:E) -> 0 | I16: ㉖ | J16: =IF(H16="",0,SUMIF(仕訳帳!I:I,H16,仕訳帳!E:E)-SUMIF(仕訳帳!J:J,H16,仕訳帳!E:E)) -> 0 | L16: 青色申告特別控除前の所得金額 （㉝+㊲－㊷） | O16: ㊸ | P16: =J23+P38-P43 -> 0
C17: 旅費交通費 | D17: ⑪ | E17: =SUMIF(仕訳帳!I:I,C17,仕訳帳!E:E)-SUMIF(仕訳帳!J:J,C17,仕訳帳!E:E) -> 0 | I17: ㉗ | J17: =IF(H17="",0,SUMIF(仕訳帳!I:I,H17,仕訳帳!E:E)-SUMIF(仕訳帳!J:J,H17,仕訳帳!E:E)) -> 0 | L17: 青色申告特別控除額 | O17: ㊹ | P17: 650000
C18: 通信費 | D18: ⑫ | E18: =SUMIF(仕訳帳!I:I,C18,仕訳帳!E:E)-SUMIF(仕訳帳!J:J,C18,仕訳帳!E:E) -> 0 | I18: ㉘ | J18: =IF(H18="",0,SUMIF(仕訳帳!I:I,H18,仕訳帳!E:E)-SUMIF(仕訳帳!J:J,H18,仕訳帳!E:E)) -> 0 | L18: 所得金額 （㊸－㊹） | O18: ㊺ | P18: =MAX(0,P16-P17) -> 0
C19: 広告宣伝費 | D19: ⑬ | E19: =SUMIF(仕訳帳!I:I,C19,仕訳帳!E:E)-SUMIF(仕訳帳!J:J,C19,仕訳帳!E:E) -> 0 | I19: ㉙ | J19: =IF(H19="",0,SUMIF(仕訳帳!I:I,H19,仕訳帳!E:E)-SUMIF(仕訳帳!J:J,H19,仕訳帳!E:E)) -> 0
C20: 接待交際費 | D20: ⑭ | E20: =SUMIF(仕訳帳!I:I,C20,仕訳帳!E:E)-SUMIF(仕訳帳!J:J,C20,仕訳帳!E:E) -> 0 | I20: ㉚ | J20: =IF(H20="",0,SUMIF(仕訳帳!I:I,H20,仕訳帳!E:E)-SUMIF(仕訳帳!J:J,H20,仕訳帳!E:E)) -> 0
C21: 損害保険料 | D21: ⑮ | E21: =SUMIF(仕訳帳!I:I,C21,仕訳帳!E:E)-SUMIF(仕訳帳!J:J,C21,仕訳帳!E:E) -> 0 | H21: 雑費 | I21: ㉛ | J21: =IF(H21="",0,SUMIF(仕訳帳!I:I,H21,仕訳帳!E:E)-SUMIF(仕訳帳!J:J,H21,仕訳帳!E:E)) -> 0
C22: 修繕費 | D22: ⑯ | E22: =SUMIF(仕訳帳!I:I,C22,仕訳帳!E:E)-SUMIF(仕訳帳!J:J,C22,仕訳帳!E:E) -> 0 | H22: 計 | I22: ㉜ | J22: =SUM(J7:J21,E14:E22) -> 0
G23: 差引金額 （⑦－⑫） | I23: ㉝ | J23: =E13-J22 -> 0

Sheet ②月別売上ほか
B3: ○月別売上金額及び仕入金額 | G3: ○給料賃金の内訳
B4: 月 | C4: 売上(収入)金額 円 | D4: 仕入金額 円
B5: 1 | C5: =SUMPRODUCT((MONTH(仕訳帳!C$4:C$999)=B5)*(TEXT(仕訳帳!G$4:G$999,"0")="1"),仕訳帳!H$4:H$999)-SUMPRODUCT((MONTH(仕訳帳!C$4:C$999)=B5)*(TEXT(仕訳帳!D$4:D$999,"0")="1"),仕訳帳!H$4:H$999) -> 0 | D5: =SUMPRODUCT((MONTH(仕訳帳!C$4:C$999)=B5)*(仕訳帳!D$4:D$999=3),仕訳帳!H$4:H$999)-SUMPRODUCT((MONTH(仕訳帳!C$4:C$999)=B5)*(仕訳帳!G$4:G$999=3),仕訳帳!H$4:H$999) -> 0
B6: 2 | C6: =SUMPRODUCT((MONTH(仕訳帳!C$4:C$999)=B6)*(TEXT(仕訳帳!G$4:G$999,"0")="1"),仕訳帳!H$4:H$999)-SUMPRODUCT((MONTH(仕訳帳!C$4:C$999)=B6)*(TEXT(仕訳帳!D$4:D$999,"0")="1"),仕訳帳!H$4:H$999) -> 0 | D6: =SUMPRODUCT((MONTH(仕訳帳!C$4:C$999)=B6)*(仕訳帳!D$4:D$999=3),仕訳帳!H$4:H$999)-SUMPRODUCT((MONTH(仕訳帳!C$4:C$999)=B6)*(仕訳帳!G$4:G$999=3),仕訳帳!H$4:H$999) -> 0
B7: 3 | C7: =SUMPRODUCT((MONTH(仕訳帳!C$4:C$999)=B7)*(TEXT(仕訳帳!G$4:G$999,"0")="1"),仕訳帳!H$4:H$999)-SUMPRODUCT((MONTH(仕訳帳!C$4:C$999)=B7)*(TEXT(仕訳帳!D$4:D$999,"0")="1"),仕訳帳!H$4:H$999) -> 0 | D7: =SUMPRODUCT((MONTH(仕訳帳!C$4:C$999)=B7)*(仕訳帳!D$4:D$999=3),仕訳帳!H$4:H$999)-SUMPRODUCT((MONTH(仕訳帳!C$4:C$999)=B7)*(仕訳帳!G$4:G$999=3),仕訳帳!H$4:H$999) -> 0 | J7: 略
B8: 4 | C8: =SUMPRODUCT((MONTH(仕訳帳!C$4:C$999)=B8)*(TEXT(仕訳帳!G$4:G$999,"0")="1"),仕訳帳!H$4:H$999)-SUMPRODUCT((MONTH(仕訳帳!C$4:C$999)=B8)*(TEXT(仕訳帳!D$4:D$999,"0")="1"),仕訳帳!H$4:H$999) -> 0 | D8: =SUMPRODUCT((MONTH(仕訳帳!C$4:C$999)=B8)*(仕訳帳!D$4:D$999=3),仕訳帳!H$4:H$999)-SUMPRODUCT((MONTH(仕訳帳!C$4:C$999)=B8)*(仕訳帳!G$4:G$999=3),仕訳帳!H$4:H$999) -> 0
B9: 5 | C9: =SUMPRODUCT((MONTH(仕訳帳!C$4:C$999)=B9)*(TEXT(仕訳帳!G$4:G$999,"0")="1"),仕訳帳!H$4:H$999)-SUMPRODUCT((MONTH(仕訳帳!C$4:C$999)=B9)*(TEXT(仕訳帳!D$4:D$999,"0")="1"),仕訳帳!H$4:H$999) -> 0 | D9: =SUMPRODUCT((MONTH(仕訳帳!C$4:C$999)=B9)*(仕訳帳!D$4:D$999=3),仕訳帳!H$4:H$999)-SUMPRODUCT((MONTH(仕訳帳!C$4:C$999)=B9)*(仕訳帳!G$4:G$999=3),仕訳帳!H$4:H$999) -> 0
B10: 6 | C10: =SUMPRODUCT((MONTH(仕訳帳!C$4:C$999)=B10)*(TEXT(仕訳帳!G$4:G$999,"0")="1"),仕訳帳!H$4:H$999)-SUMPRODUCT((MONTH(仕訳帳!C$4:C$999)=B10)*(TEXT(仕訳帳!D$4:D$999,"0")="1"),仕訳帳!H$4:H$999) -> 0 | D10: =SUMPRODUCT((MONTH(仕訳帳!C$4:C$999)=B10)*(仕訳帳!D$4:D$999=3),仕訳帳!H$4:H$999)-SUMPRODUCT((MONTH(仕訳帳!C$4:C$999)=B10)*(仕訳帳!G$4:G$999=3),仕訳帳!H$4:H$999) -> 0
B11: 7 | C11: =SUMPRODUCT((MONTH(仕訳帳!C$4:C$999)=B11)*(TEXT(仕訳帳!G$4:G$999,"0")="1"),仕訳帳!H$4:H$999)-SUMPRODUCT((MONTH(仕訳帳!C$4:C$999)=B11)*(TEXT(仕訳帳!D$4:D$999,"0")="1"),仕訳帳!H$4:H$999) -> 0 | D11: =SUMPRODUCT((MONTH(仕訳帳!C$4:C$999)=B11)*(仕訳帳!D$4:D$999=3),仕訳帳!H$4:H$999)-SUMPRODUCT((MONTH(仕訳帳!C$4:C$999)=B11)*(仕訳帳!G$4:G$999=3),仕訳帳!H$4:H$999) -> 0
B12: 8 | C12: =SUMPRODUCT((MONTH(仕訳帳!C$4:C$999)=B12)*(TEXT(仕訳帳!G$4:G$999,"0")="1"),仕訳帳!H$4:H$999)-SUMPRODUCT((MONTH(仕訳帳!C$4:C$999)=B12)*(TEXT(仕訳帳!D$4:D$999,"0")="1"),仕訳帳!H$4:H$999) -> 0 | D12: =SUMPRODUCT((MONTH(仕訳帳!C$4:C$999)=B12)*(仕訳帳!D$4:D$999=3),仕訳帳!H$4:H$999)-SUMPRODUCT((MONTH(仕訳帳!C$4:C$999)=B12)*(仕訳帳!G$4:G$999=3),仕訳帳!H$4:H$999) -> 0 | G12: ○専従者給与の内訳
B13: 9 | C13: =SUMPRODUCT((MONTH(仕訳帳!C$4:C$999)=B13)*(TEXT(仕訳帳!G$4:G$999,"0")="1"),仕訳帳!H$4:H$999)-SUMPRODUCT((MONTH(仕訳帳!C$4:C$999)=B13)*(TEXT(仕訳帳!D$4:D$999,"0")="1"),仕訳帳!H$4:H$999) -> 0 | D13: =SUMPRODUCT((MONTH(仕訳帳!C$4:C$999)=B13)*(仕訳帳!D$4:D$999=3),仕訳帳!H$4:H$999)-SUMPRODUCT((MONTH(仕訳帳!C$4:C$999)=B13)*(仕訳帳!G$4:G$999=3),仕訳帳!H$4:H$999) -> 0
B14: 10 | C14: =SUMPRODUCT((MONTH(仕訳帳!C$4:C$999)=B14)*(TEXT(仕訳帳!G$4:G$999,"0")="1"),仕訳帳!H$4:H$999)-SUMPRODUCT((MONTH(仕訳帳!C$4:C$999)=B14)*(TEXT(仕訳帳!D$4:D$999,"0")="1"),仕訳帳!H$4:H$999) -> 0 | D14: =SUMPRODUCT((MONTH(仕訳帳!C$4:C$999)=B14)*(仕訳帳!D$4:D$999=3),仕訳帳!H$4:H$999)-SUMPRODUCT((MONTH(仕訳帳!C$4:C$999)=B14)*(仕訳帳!G$4:G$999=3),仕訳帳!H$4:H$999) -> 0
B15: 11 | C15: =SUMPRODUCT((MONTH(仕訳帳!C$4:C$999)=B15)*(TEXT(仕訳帳!G$4:G$999,"0")="1"),仕訳帳!H$4:H$999)-SUMPRODUCT((MONTH(仕訳帳!C$4:C$999)=B15)*(TEXT(仕訳帳!D$4:D$999,"0")="1"),仕訳帳!H$4:H$999) -> 0 | D15: =SUMPRODUCT((MONTH(仕訳帳!C$4:C$999)=B15)*(仕訳帳!D$4:D$999=3),仕訳帳!H$4:H$999)-SUMPRODUCT((MONTH(仕訳帳!C$4:C$999)=B15)*(仕訳帳!G$4:G$999=3),仕訳帳!H$4:H$999) -> 0
B16: 12 | C16: =SUMPRODUCT((MONTH(仕訳帳!C$4:C$999)=B16)*(TEXT(仕訳帳!G$4:G$999,"0")="1"),仕訳帳!H$4:H$999)-SUMPRODUCT((MONTH(仕訳帳!C$4:C$999)=B16)*(TEXT(仕訳帳!D$4:D$999,"0")="1"),仕訳帳!H$4:H$999) -> 0 | D16: =SUMPRODUCT((MONTH(仕訳帳!C$4:C$999)=B16)*(仕訳帳!D$4:D$999=3),仕訳帳!H$4:H$999)-SUMPRODUCT((MONTH(仕訳帳!C$4:C$999)=B16)*(仕訳帳!G$4:G$999=3),仕訳帳!H$4:H$999) -> 0 | J16: 略
B17: 家事消費等
B18: 雑収入
B19: 計 | C19: =SUM(C5:C18) -> 0 | D19: =SUM(D5:D18) -> 0
B20: うち軽減税率対象 | G20: ○地帯家賃の内訳
B22: ○貸倒引当金繰入額の計算
J23: 略
C25: 略
G26: ○青色申告特別控除額の計算
N27: 金額 円
G28: 本年度分の不動産所得の金額 | M28: ⑥
G29: 青色申告特別控除前の所得金額 | M29: ⑦
G30: 青色申告特別控除 | I30: ６５万又は５５万円と⑥のいずれか少ない方の金額 | M30: ⑧
G31: を受ける場合 | I31: 青色申告特別控除額 | M31: ⑨
G32: 上記以外の場合 | I32: １０万円と⑥のいずれか少ない方の金額 | M32: ⑧
I33: 青色申告特別控除額 | M33: ⑨

Sheet ③減価償却ほか
B3: ○売上（収入）金額の明細 | O3: ◎本年中における特殊事項
G7: 略
B11: ○仕入金額の明細
G15: 略
B20: ○減価償却費の計算
B31: ○利子割引料の内訳
J33: 略
B35: ○税理士・弁護士等の報酬・料金の内訳
J37: 略

Sheet ④貸借対照表 
A1: 貸借対照表（資産負債調）
K2: 製造原価の計算
B3: 資産の部 | G3: 負債・資本の部
A4: コード | B4: 科目 | C4: １月１日（期首） | D4: １２月３１日（期末） | F4: コード | G4: 科目 | H4: １月１日（期首） | I4: １２月３１日（期末）
A5: 101 | B5: 現金 | C5: =IF(B5="棚卸資産",IF(ISNUMBER(MATCH("期首商品（製品)棚卸高",仕訳帳!$I:$I,0)),INDEX(仕訳帳!$E:$E,MATCH("期首商品（製品)棚卸高",仕訳帳!$I:$I,0)),""),IF(SUMPRODUCT((ISNUMBER(仕訳帳!$C$4:$C$999))*(MONTH(仕訳帳!$C$4:$C$999)=1)*(DAY(仕訳帳!$C$4:$C$999)=1)*(仕訳帳!$I$4:$I$999=B5)*(仕訳帳!$J$4:$J$999<>"売上（収入）")*(ISNUMBER(仕訳帳!$E$4:$E$999)))=0,"",SUMPRODUCT((ISNUMBER(仕訳帳!$C$4:$C$999))*(MONTH(仕訳帳!$C$4:$C$999)=1)*(DAY(仕訳帳!$C$4:$C$999)=1)*(仕訳帳!$I$4:$I$999=B5)*(仕訳帳!$J$4:$J$999<>"売上（収入）")*(ISNUMBER(仕訳帳!$E$4:$E$999))*(仕訳帳!$E$4:$E$999)))) | D5: {=IF(B5="棚卸資産",IF(SUMIF(仕訳帳!J:J,"期末商品（製品)棚卸高",仕訳帳!H:H)=0,"",SUMIF(仕訳帳!J:J,"期末商品（製品)棚卸高",仕訳帳!H:H)),IF(SUMIF(仕訳帳!I:I,B5,仕訳帳!E:E)-SUMIF(仕訳帳!J:J,B5,仕訳帳!H:H)=0,"",SUMIF(仕訳帳!I:I,B5,仕訳帳!E:E)-SUMIF(仕訳帳!J:J,B5,仕訳帳!H:H)))} | F5: 151 | G5: 支払手形 | H5: =IF(SUMPRODUCT((ISNUMBER(仕訳帳!$C$4:$C$999))*(MONTH(仕訳帳!$C$4:$C$999)=1)*(DAY(仕訳帳!$C$4:$C$999)=1)*(仕訳帳!$J$4:$J$999=G5)*(ISNUMBER(仕訳帳!$H$4:$H$999)))=0,"",SUMPRODUCT((ISNUMBER(仕訳帳!$C$4:$C$999))*(MONTH(仕訳帳!$C$4:$C$999)=1)*(DAY(仕訳帳!$C$4:$C$999)=1)*(仕訳帳!$J$4:$J$999=G5)*(ISNUMBER(仕訳帳!$H$4:$H$999))*(仕訳帳!$H$4:$H$999))) | I5: {=IF(SUMIF(仕訳帳!J:J,G5,仕訳帳!H:H)-SUMIF(仕訳帳!I:I,G5,仕訳帳!E:E)=0,"",SUMIF(仕訳帳!J:J,G5,仕訳帳!H:H)-SUMIF(仕訳帳!I:I,G5,仕訳帳!E:E))}
A6: 102 | B6: 当座預金 | C6: =IF(B6="棚卸資産",IF(ISNUMBER(MATCH("期首商品（製品)棚卸高",仕訳帳!$I:$I,0)),INDEX(仕訳帳!$E:$E,MATCH("期首商品（製品)棚卸高",仕訳帳!$I:$I,0)),""),IF(SUMPRODUCT((ISNUMBER(仕訳帳!$C$4:$C$999))*(MONTH(仕訳帳!$C$4:$C$999)=1)*(DAY(仕訳帳!$C$4:$C$999)=1)*(仕訳帳!$I$4:$I$999=B6)*(仕訳帳!$J$4:$J$999<>"売上（収入）")*(ISNUMBER(仕訳帳!$E$4:$E$999)))=0,"",SUMPRODUCT((ISNUMBER(仕訳帳!$C$4:$C$999))*(MONTH(仕訳帳!$C$4:$C$999)=1)*(DAY(仕訳帳!$C$4:$C$999)=1)*(仕訳帳!$I$4:$I$999=B6)*(仕訳帳!$J$4:$J$999<>"売上（収入）")*(ISNUMBER(仕訳帳!$E$4:$E$999))*(仕訳帳!$E$4:$E$999)))) | D6: {=IF(B6="棚卸資産",IF(SUMIF(仕訳帳!J:J,"期末商品（製品)棚卸高",仕訳帳!H:H)=0,"",SUMIF(仕訳帳!J:J,"期末商品（製品)棚卸高",仕訳帳!H:H)),IF(SUMIF(仕訳帳!I:I,B6,仕訳帳!E:E)-SUMIF(仕訳帳!J:J,B6,仕訳帳!H:H)=0,"",SUMIF(仕訳帳!I:I,B6,仕訳帳!E:E)-SUMIF(仕訳帳!J:J,B6,仕訳帳!H:H)))} | F6: 152 | G6: 買掛金 | H6: =IF(SUMPRODUCT((ISNUMBER(仕訳帳!$C$4:$C$999))*(MONTH(仕訳帳!$C$4:$C$999)=1)*(DAY(仕訳帳!$C$4:$C$999)=1)*(仕訳帳!$J$4:$J$999=G6)*(ISNUMBER(仕訳帳!$H$4:$H$999)))=0,"",SUMPRODUCT((ISNUMBER(仕訳帳!$C$4:$C$999))*(MONTH(仕訳帳!$C$4:$C$999)=1)*(DAY(仕訳帳!$C$4:$C$999)=1)*(仕訳帳!$J$4:$J$999=G6)*(ISNUMBER(仕訳帳!$H$4:$H$999))*(仕訳帳!$H$4:$H$999))) | I6: {=IF(SUMIF(仕訳帳!J:J,G6,仕訳帳!H:H)-SUMIF(仕訳帳!I:I,G6,仕訳帳!E:E)=0,"",SUMIF(仕訳帳!J:J,G6,仕訳帳!H:H)-SUMIF(仕訳帳!I:I,G6,仕訳帳!E:E))}
A7: 103 | B7: 定期預金 | C7: =IF(B7="棚卸資産",IF(ISNUMBER(MATCH("期首商品（製品)棚卸高",仕訳帳!$I:$I,0)),INDEX(仕訳帳!$E:$E,MATCH("期首商品（製品)棚卸高",仕訳帳!$I:$I,0)),""),IF(SUMPRODUCT((ISNUMBER(仕訳帳!$C$4:$C$999))*(MONTH(仕訳帳!$C$4:$C$999)=1)*(DAY(仕訳帳!$C$4:$C$999)=1)*(仕訳帳!$I$4:$I$999=B7)*(仕訳帳!$J$4:$J$999<>"売上（収入）")*(ISNUMBER(仕訳帳!$E$4:$E$999)))=0,"",SUMPRODUCT((ISNUMBER(仕訳帳!$C$4:$C$999))*(MONTH(仕訳帳!$C$4:$C$999)=1)*(DAY(仕訳帳!$C$4:$C$999)=1)*(仕訳帳!$I$4:$I$999=B7)*(仕訳帳!$J$4:$J$999<>"売上（収入）")*(ISNUMBER(仕訳帳!$E$4:$E$999))*(仕訳帳!$E$4:$E$999)))) | D7: {=IF(B7="棚卸資産",IF(SUMIF(仕訳帳!J:J,"期末商品（製品)棚卸高",仕訳帳!H:H)=0,"",SUMIF(仕訳帳!J:J,"期末商品（製品)棚卸高",仕訳帳!H:H)),IF(SUMIF(仕訳帳!I:I,B7,仕訳帳!E:E)-SUMIF(仕訳帳!J:J,B7,仕訳帳!H:H)=0,"",SUMIF(仕訳帳!I:I,B7,仕訳帳!E:E)-SUMIF(仕訳帳!J:J,B7,仕訳帳!H:H)))} | F7: 153 | G7: 借入金 | H7: =IF(SUMPRODUCT((ISNUMBER(仕訳帳!$C$4:$C$999))*(MONTH(仕訳帳!$C$4:$C$999)=1)*(DAY(仕訳帳!$C$4:$C$999)=1)*(仕訳帳!$J$4:$J$999=G7)*(ISNUMBER(仕訳帳!$H$4:$H$999)))=0,"",SUMPRODUCT((ISNUMBER(仕訳帳!$C$4:$C$999))*(MONTH(仕訳帳!$C$4:$C$999)=1)*(DAY(仕訳帳!$C$4:$C$999)=1)*(仕訳帳!$J$4:$J$999=G7)*(ISNUMBER(仕訳帳!$H$4:$H$999))*(仕訳帳!$H$4:$H$999))) | I7: {=IF(SUMIF(仕訳帳!J:J,G7,仕訳帳!H:H)-SUMIF(仕訳帳!I:I,G7,仕訳帳!E:E)=0,"",SUMIF(仕訳帳!J:J,G7,仕訳帳!H:H)-SUMIF(仕訳帳!I:I,G7,仕訳帳!E:E))}
A8: 104 | B8: その他の預金 | C8: =IF(B8="棚卸資産",IF(ISNUMBER(MATCH("期首商品（製品)棚卸高",仕訳帳!$I:$I,0)),INDEX(仕訳帳!$E:$E,MATCH("期首商品（製品)棚卸高",仕訳帳!$I:$I,0)),""),IF(SUMPRODUCT((ISNUMBER(仕訳帳!$C$4:$C$999))*(MONTH(仕訳帳!$C$4:$C$999)=1)*(DAY(仕訳帳!$C$4:$C$999)=1)*(仕訳帳!$I$4:$I$999=B8)*(仕訳帳!$J$4:$J$999<>"売上（収入）")*(ISNUMBER(仕訳帳!$E$4:$E$999)))=0,"",SUMPRODUCT((ISNUMBER(仕訳帳!$C$4:$C$999))*(MONTH(仕訳帳!$C$4:$C$999)=1)*(DAY(仕訳帳!$C$4:$C$999)=1)*(仕訳帳!$I$4:$I$999=B8)*(仕訳帳!$J$4:$J$999<>"売上（収入）")*(ISNUMBER(仕訳帳!$E$4:$E$999))*(仕訳帳!$E$4:$E$999)))) | D8: {=IF(B8="棚卸資産",IF(SUMIF(仕訳帳!J:J,"期末商品（製品)棚卸高",仕訳帳!H:H)=0,"",SUMIF(仕訳帳!J:J,"期末商品（製品)棚卸高",仕訳帳!H:H)),IF(SUMIF(仕訳帳!I:I,B8,仕訳帳!E:E)-SUMIF(仕訳帳!J:J,B8,仕訳帳!H:H)=0,"",SUMIF(仕訳帳!I:I,B8,仕訳帳!E:E)-SUMIF(仕訳帳!J:J,B8,仕訳帳!H:H)))} | F8: 154 | G8: 未払金 | H8: =IF(SUMPRODUCT((ISNUMBER(仕訳帳!$C$4:$C$999))*(MONTH(仕訳帳!$C$4:$C$999)=1)*(DAY(仕訳帳!$C$4:$C$999)=1)*(仕訳帳!$J$4:$J$999=G8)*(ISNUMBER(仕訳帳!$H$4:$H$999)))=0,"",SUMPRODUCT((ISNUMBER(仕訳帳!$C$4:$C$999))*(MONTH(仕訳帳!$C$4:$C$999)=1)*(DAY(仕訳帳!$C$4:$C$999)=1)*(仕訳帳!$J$4:$J$999=G8)*(ISNUMBER(仕訳帳!$H$4:$H$999))*(仕訳帳!$H$4:$H$999))) | I8: {=IF(SUMIF(仕訳帳!J:J,G8,仕訳帳!H:H)-SUMIF(仕訳帳!I:I,G8,仕訳帳!E:E)=0,"",SUMIF(仕訳帳!J:J,G8,仕訳帳!H:H)-SUMIF(仕訳帳!I:I,G8,仕訳帳!E:E))}
A9: 105 | B9: 受取手形 | C9: =IF(B9="棚卸資産",IF(ISNUMBER(MATCH("期首商品（製品)棚卸高",仕訳帳!$I:$I,0)),INDEX(仕訳帳!$E:$E,MATCH("期首商品（製品)棚卸高",仕訳帳!$I:$I,0)),""),IF(SUMPRODUCT((ISNUMBER(仕訳帳!$C$4:$C$999))*(MONTH(仕訳帳!$C$4:$C$999)=1)*(DAY(仕訳帳!$C$4:$C$999)=1)*(仕訳帳!$I$4:$I$999=B9)*(仕訳帳!$J$4:$J$999<>"売上（収入）")*(ISNUMBER(仕訳帳!$E$4:$E$999)))=0,"",SUMPRODUCT((ISNUMBER(仕訳帳!$C$4:$C$999))*(MONTH(仕訳帳!$C$4:$C$999)=1)*(DAY(仕訳帳!$C$4:$C$999)=1)*(仕訳帳!$I$4:$I$999=B9)*(仕訳帳!$J$4:$J$999<>"売上（収入）")*(ISNUMBER(仕訳帳!$E$4:$E$999))*(仕訳帳!$E$4:$E$999)))) | D9: {=IF(B9="棚卸資産",IF(SUMIF(仕訳帳!J:J,"期末商品（製品)棚卸高",仕訳帳!H:H)=0,"",SUMIF(仕訳帳!J:J,"期末商品（製品)棚卸高",仕訳帳!H:H)),IF(SUMIF(仕訳帳!I:I,B9,仕訳帳!E:E)-SUMIF(仕訳帳!J:J,B9,仕訳帳!H:H)=0,"",SUMIF(仕訳帳!I:I,B9,仕訳帳!E:E)-SUMIF(仕訳帳!J:J,B9,仕訳帳!H:H)))} | F9: 155 | G9: 前受金 | H9: =IF(SUMPRODUCT((ISNUMBER(仕訳帳!$C$4:$C$999))*(MONTH(仕訳帳!$C$4:$C$999)=1)*(DAY(仕訳帳!$C$4:$C$999)=1)*(仕訳帳!$J$4:$J$999=G9)*(ISNUMBER(仕訳帳!$H$4:$H$999)))=0,"",SUMPRODUCT((ISNUMBER(仕訳帳!$C$4:$C$999))*(MONTH(仕訳帳!$C$4:$C$999)=1)*(DAY(仕訳帳!$C$4:$C$999)=1)*(仕訳帳!$J$4:$J$999=G9)*(ISNUMBER(仕訳帳!$H$4:$H$999))*(仕訳帳!$H$4:$H$999))) | I9: {=IF(SUMIF(仕訳帳!J:J,G9,仕訳帳!H:H)-SUMIF(仕訳帳!I:I,G9,仕訳帳!E:E)=0,"",SUMIF(仕訳帳!J:J,G9,仕訳帳!H:H)-SUMIF(仕訳帳!I:I,G9,仕訳帳!E:E))}
A10: 106 | B10: 売掛金 | C10: =IF(B10="棚卸資産",IF(ISNUMBER(MATCH("期首商品（製品)棚卸高",仕訳帳!$I:$I,0)),INDEX(仕訳帳!$E:$E,MATCH("期首商品（製品)棚卸高",仕訳帳!$I:$I,0)),""),IF(SUMPRODUCT((ISNUMBER(仕訳帳!$C$4:$C$999))*(MONTH(仕訳帳!$C$4:$C$999)=1)*(DAY(仕訳帳!$C$4:$C$999)=1)*(仕訳帳!$I$4:$I$999=B10)*(仕訳帳!$J$4:$J$999<>"売上（収入）")*(ISNUMBER(仕訳帳!$E$4:$E$999)))=0,"",SUMPRODUCT((ISNUMBER(仕訳帳!$C$4:$C$999))*(MONTH(仕訳帳!$C$4:$C$999)=1)*(DAY(仕訳帳!$C$4:$C$999)=1)*(仕訳帳!$I$4:$I$999=B10)*(仕訳帳!$J$4:$J$999<>"売上（収入）")*(ISNUMBER(仕訳帳!$E$4:$E$999))*(仕訳帳!$E$4:$E$999)))) | D10: {=IF(B10="棚卸資産",IF(SUMIF(仕訳帳!J:J,"期末商品（製品)棚卸高",仕訳帳!H:H)=0,"",SUMIF(仕訳帳!J:J,"期末商品（製品)棚卸高",仕訳帳!H:H)),IF(SUMIF(仕訳帳!I:I,B10,仕訳帳!E:E)-SUMIF(仕訳帳!J:J,B10,仕訳帳!H:H)=0,"",SUMIF(仕訳帳!I:I,B10,仕訳帳!E:E)-SUMIF(仕訳帳!J:J,B10,仕訳帳!H:H)))} | F10: 156 | G10: 預り金 | H10: =IF(SUMPRODUCT((ISNUMBER(仕訳帳!$C$4:$C$999))*(MONTH(仕訳帳!$C$4:$C$999)=1)*(DAY(仕訳帳!$C$4:$C$999)=1)*(仕訳帳!$J$4:$J$999=G10)*(ISNUMBER(仕訳帳!$H$4:$H$999)))=0,"",SUMPRODUCT((ISNUMBER(仕訳帳!$C$4:$C$999))*(MONTH(仕訳帳!$C$4:$C$999)=1)*(DAY(仕訳帳!$C$4:$C$999)=1)*(仕訳帳!$J$4:$J$999=G10)*(ISNUMBER(仕訳帳!$H$4:$H$999))*(仕訳帳!$H$4:$H$999))) | I10: {=IF(SUMIF(仕訳帳!J:J,G10,仕訳帳!H:H)-SUMIF(仕訳帳!I:I,G10,仕訳帳!E:E)=0,"",SUMIF(仕訳帳!J:J,G10,仕訳帳!H:H)-SUMIF(仕訳帳!I:I,G10,仕訳帳!E:E))}
A11: 107 | B11: 有価証券 | C11: =IF(B11="棚卸資産",IF(ISNUMBER(MATCH("期首商品（製品)棚卸高",仕訳帳!$I:$I,0)),INDEX(仕訳帳!$E:$E,MATCH("期首商品（製品)棚卸高",仕訳帳!$I:$I,0)),""),IF(SUMPRODUCT((ISNUMBER(仕訳帳!$C$4:$C$999))*(MONTH(仕訳帳!$C$4:$C$999)=1)*(DAY(仕訳帳!$C$4:$C$999)=1)*(仕訳帳!$I$4:$I$999=B11)*(仕訳帳!$J$4:$J$999<>"売上（収入）")*(ISNUMBER(仕訳帳!$E$4:$E$999)))=0,"",SUMPRODUCT((ISNUMBER(仕訳帳!$C$4:$C$999))*(MONTH(仕訳帳!$C$4:$C$999)=1)*(DAY(仕訳帳!$C$4:$C$999)=1)*(仕訳帳!$I$4:$I$999=B11)*(仕訳帳!$J$4:$J$999<>"売上（収入）")*(ISNUMBER(仕訳帳!$E$4:$E$999))*(仕訳帳!$E$4:$E$999)))) | D11: {=IF(B11="棚卸資産",IF(SUMIF(仕訳帳!J:J,"期末商品（製品)棚卸高",仕訳帳!H:H)=0,"",SUMIF(仕訳帳!J:J,"期末商品（製品)棚卸高",仕訳帳!H:H)),IF(SUMIF(仕訳帳!I:I,B11,仕訳帳!E:E)-SUMIF(仕訳帳!J:J,B11,仕訳帳!H:H)=0,"",SUMIF(仕訳帳!I:I,B11,仕訳帳!E:E)-SUMIF(仕訳帳!J:J,B11,仕訳帳!H:H)))} | H11: =IF(SUMPRODUCT((ISNUMBER(仕訳帳!$C$4:$C$999))*(MONTH(仕訳帳!$C$4:$C$999)=1)*(DAY(仕訳帳!$C$4:$C$999)=1)*(仕訳帳!$J$4:$J$999=G11)*(ISNUMBER(仕訳帳!$H$4:$H$999)))=0,"",SUMPRODUCT((ISNUMBER(仕訳帳!$C$4:$C$999))*(MONTH(仕訳帳!$C$4:$C$999)=1)*(DAY(仕訳帳!$C$4:$C$999)=1)*(仕訳帳!$J$4:$J$999=G11)*(ISNUMBER(仕訳帳!$H$4:$H$999))*(仕訳帳!$H$4:$H$999))) | I11: {=IF(SUMIF(仕訳帳!J:J,G11,仕訳帳!H:H)-SUMIF(仕訳帳!I:I,G11,仕訳帳!E:E)=0,"",SUMIF(仕訳帳!J:J,G11,仕訳帳!H:H)-SUMIF(仕訳帳!I:I,G11,仕訳帳!E:E))}
A12: 108 | B12: 棚卸資産 | C12: =IF(B12="棚卸資産",IF(ISNUMBER(MATCH("期首商品（製品)棚卸高",仕訳帳!$I:$I,0)),INDEX(仕訳帳!$E:$E,MATCH("期首商品（製品)棚卸高",仕訳帳!$I:$I,0)),""),IF(SUMPRODUCT((ISNUMBER(仕訳帳!$C$4:$C$999))*(MONTH(仕訳帳!$C$4:$C$999)=1)*(DAY(仕訳帳!$C$4:$C$999)=1)*(仕訳帳!$I$4:$I$999=B12)*(仕訳帳!$J$4:$J$999<>"売上（収入）")*(ISNUMBER(仕訳帳!$E$4:$E$999)))=0,"",SUMPRODUCT((ISNUMBER(仕訳帳!$C$4:$C$999))*(MONTH(仕訳帳!$C$4:$C$999)=1)*(DAY(仕訳帳!$C$4:$C$999)=1)*(仕訳帳!$I$4:$I$999=B12)*(仕訳帳!$J$4:$J$999<>"売上（収入）")*(ISNUMBER(仕訳帳!$E$4:$E$999))*(仕訳帳!$E$4:$E$999)))) | D12: {=IF(B12="棚卸資産",IF(SUMIF(仕訳帳!J:J,"期末商品（製品)棚卸高",仕訳帳!H:H)=0,"",SUMIF(仕訳帳!J:J,"期末商品（製品)棚卸高",仕訳帳!H:H)),IF(SUMIF(仕訳帳!I:I,B12,仕訳帳!E:E)-SUMIF(仕訳帳!J:J,B12,仕訳帳!H:H)=0,"",SUMIF(仕訳帳!I:I,B12,仕訳帳!E:E)-SUMIF(仕訳帳!J:J,B12,仕訳帳!H:H)))} | H12: =IF(SUMPRODUCT((ISNUMBER(仕訳帳!$C$4:$C$999))*(MONTH(仕訳帳!$C$4:$C$999)=1)*(DAY(仕訳帳!$C$4:$C$999)=1)*(仕訳帳!$J$4:$J$999=G12)*(ISNUMBER(仕訳帳!$H$4:$H$999)))=0,"",SUMPRODUCT((ISNUMBER(仕訳帳!$C$4:$C$999))*(MONTH(仕訳帳!$C$4:$C$999)=1)*(DAY(仕訳帳!$C$4:$C$999)=1)*(仕訳帳!$J$4:$J$999=G12)*(ISNUMBER(仕訳帳!$H$4:$H$999))*(仕訳帳!$H$4:$H$999))) | I12: {=IF(SUMIF(仕訳帳!J:J,G12,仕訳帳!H:H)-SUMIF(仕訳帳!I:I,G12,仕訳帳!E:E)=0,"",SUMIF(仕訳帳!J:J,G12,仕訳帳!H:H)-SUMIF(仕訳帳!I:I,G12,仕訳帳!E:E))}
A13: 109 | B13: 前払い金 | C13: =IF(B13="棚卸資産",IF(ISNUMBER(MATCH("期首商品（製品)棚卸高",仕訳帳!$I:$I,0)),INDEX(仕訳帳!$E:$E,MATCH("期首商品（製品)棚卸高",仕訳帳!$I:$I,0)),""),IF(SUMPRODUCT((ISNUMBER(仕訳帳!$C$4:$C$999))*(MONTH(仕訳帳!$C$4:$C$999)=1)*(DAY(仕訳帳!$C$4:$C$999)=1)*(仕訳帳!$I$4:$I$999=B13)*(仕訳帳!$J$4:$J$999<>"売上（収入）")*(ISNUMBER(仕訳帳!$E$4:$E$999)))=0,"",SUMPRODUCT((ISNUMBER(仕訳帳!$C$4:$C$999))*(MONTH(仕訳帳!$C$4:$C$999)=1)*(DAY(仕訳帳!$C$4:$C$999)=1)*(仕訳帳!$I$4:$I$999=B13)*(仕訳帳!$J$4:$J$999<>"売上（収入）")*(ISNUMBER(仕訳帳!$E$4:$E$999))*(仕訳帳!$E$4:$E$999)))) | D13: {=IF(B13="棚卸資産",IF(SUMIF(仕訳帳!J:J,"期末商品（製品)棚卸高",仕訳帳!H:H)=0,"",SUMIF(仕訳帳!J:J,"期末商品（製品)棚卸高",仕訳帳!H:H)),IF(SUMIF(仕訳帳!I:I,B13,仕訳帳!E:E)-SUMIF(仕訳帳!J:J,B13,仕訳帳!H:H)=0,"",SUMIF(仕訳帳!I:I,B13,仕訳帳!E:E)-SUMIF(仕訳帳!J:J,B13,仕訳帳!H:H)))} | H13: =IF(SUMPRODUCT((ISNUMBER(仕訳帳!$C$4:$C$999))*(MONTH(仕訳帳!$C$4:$C$999)=1)*(DAY(仕訳帳!$C$4:$C$999)=1)*(仕訳帳!$J$4:$J$999=G13)*(ISNUMBER(仕訳帳!$H$4:$H$999)))=0,"",SUMPRODUCT((ISNUMBER(仕訳帳!$C$4:$C$999))*(MONTH(仕訳帳!$C$4:$C$999)=1)*(DAY(仕訳帳!$C$4:$C$999)=1)*(仕訳帳!$J$4:$J$999=G13)*(ISNUMBER(仕訳帳!$H$4:$H$999))*(仕訳帳!$H$4:$H$999))) | I13: {=IF(SUMIF(仕訳帳!J:J,G13,仕訳帳!H:H)-SUMIF(仕訳帳!I:I,G13,仕訳帳!E:E)=0,"",SUMIF(仕訳帳!J:J,G13,仕訳帳!H:H)-SUMIF(仕訳帳!I:I,G13,仕訳帳!E:E))}
A14: 110 | B14: 貸付金 | C14: =IF(B14="棚卸資産",IF(ISNUMBER(MATCH("期首商品（製品)棚卸高",仕訳帳!$I:$I,0)),INDEX(仕訳帳!$E:$E,MATCH("期首商品（製品)棚卸高",仕訳帳!$I:$I,0)),""),IF(SUMPRODUCT((ISNUMBER(仕訳帳!$C$4:$C$999))*(MONTH(仕訳帳!$C$4:$C$999)=1)*(DAY(仕訳帳!$C$4:$C$999)=1)*(仕訳帳!$I$4:$I$999=B14)*(仕訳帳!$J$4:$J$999<>"売上（収入）")*(ISNUMBER(仕訳帳!$E$4:$E$999)))=0,"",SUMPRODUCT((ISNUMBER(仕訳帳!$C$4:$C$999))*(MONTH(仕訳帳!$C$4:$C$999)=1)*(DAY(仕訳帳!$C$4:$C$999)=1)*(仕訳帳!$I$4:$I$999=B14)*(仕訳帳!$J$4:$J$999<>"売上（収入）")*(ISNUMBER(仕訳帳!$E$4:$E$999))*(仕訳帳!$E$4:$E$999)))) | D14: {=IF(B14="棚卸資産",IF(SUMIF(仕訳帳!J:J,"期末商品（製品)棚卸高",仕訳帳!H:H)=0,"",SUMIF(仕訳帳!J:J,"期末商品（製品)棚卸高",仕訳帳!H:H)),IF(SUMIF(仕訳帳!I:I,B14,仕訳帳!E:E)-SUMIF(仕訳帳!J:J,B14,仕訳帳!H:H)=0,"",SUMIF(仕訳帳!I:I,B14,仕訳帳!E:E)-SUMIF(仕訳帳!J:J,B14,仕訳帳!H:H)))} | H14: =IF(SUMPRODUCT((ISNUMBER(仕訳帳!$C$4:$C$999))*(MONTH(仕訳帳!$C$4:$C$999)=1)*(DAY(仕訳帳!$C$4:$C$999)=1)*(仕訳帳!$J$4:$J$999=G14)*(ISNUMBER(仕訳帳!$H$4:$H$999)))=0,"",SUMPRODUCT((ISNUMBER(仕訳帳!$C$4:$C$999))*(MONTH(仕訳帳!$C$4:$C$999)=1)*(DAY(仕訳帳!$C$4:$C$999)=1)*(仕訳帳!$J$4:$J$999=G14)*(ISNUMBER(仕訳帳!$H$4:$H$999))*(仕訳帳!$H$4:$H$999))) | I14: {=IF(SUMIF(仕訳帳!J:J,G14,仕訳帳!H:H)-SUMIF(仕訳帳!I:I,G14,仕訳帳!E:E)=0,"",SUMIF(仕訳帳!J:J,G14,仕訳帳!H:H)-SUMIF(仕訳帳!I:I,G14,仕訳帳!E:E))}
A15: 111 | B15: 建物 | C15: =IF(B15="棚卸資産",IF(ISNUMBER(MATCH("期首商品（製品)棚卸高",仕訳帳!$I:$I,0)),INDEX(仕訳帳!$E:$E,MATCH("期首商品（製品)棚卸高",仕訳帳!$I:$I,0)),""),IF(SUMPRODUCT((ISNUMBER(仕訳帳!$C$4:$C$999))*(MONTH(仕訳帳!$C$4:$C$999)=1)*(DAY(仕訳帳!$C$4:$C$999)=1)*(仕訳帳!$I$4:$I$999=B15)*(仕訳帳!$J$4:$J$999<>"売上（収入）")*(ISNUMBER(仕訳帳!$E$4:$E$999)))=0,"",SUMPRODUCT((ISNUMBER(仕訳帳!$C$4:$C$999))*(MONTH(仕訳帳!$C$4:$C$999)=1)*(DAY(仕訳帳!$C$4:$C$999)=1)*(仕訳帳!$I$4:$I$999=B15)*(仕訳帳!$J$4:$J$999<>"売上（収入）")*(ISNUMBER(仕訳帳!$E$4:$E$999))*(仕訳帳!$E$4:$E$999)))) | D15: {=IF(B15="棚卸資産",IF(SUMIF(仕訳帳!J:J,"期末商品（製品)棚卸高",仕訳帳!H:H)=0,"",SUMIF(仕訳帳!J:J,"期末商品（製品)棚卸高",仕訳帳!H:H)),IF(SUMIF(仕訳帳!I:I,B15,仕訳帳!E:E)-SUMIF(仕訳帳!J:J,B15,仕訳帳!H:H)=0,"",SUMIF(仕訳帳!I:I,B15,仕訳帳!E:E)-SUMIF(仕訳帳!J:J,B15,仕訳帳!H:H)))} | H15: =IF(SUMPRODUCT((ISNUMBER(仕訳帳!$C$4:$C$999))*(MONTH(仕訳帳!$C$4:$C$999)=1)*(DAY(仕訳帳!$C$4:$C$999)=1)*(仕訳帳!$J$4:$J$999=G15)*(ISNUMBER(仕訳帳!$H$4:$H$999)))=0,"",SUMPRODUCT((ISNUMBER(仕訳帳!$C$4:$C$999))*(MONTH(仕訳帳!$C$4:$C$999)=1)*(DAY(仕訳帳!$C$4:$C$999)=1)*(仕訳帳!$J$4:$J$999=G15)*(ISNUMBER(仕訳帳!$H$4:$H$999))*(仕訳帳!$H$4:$H$999))) | I15: {=IF(SUMIF(仕訳帳!J:J,G15,仕訳帳!H:H)-SUMIF(仕訳帳!I:I,G15,仕訳帳!E:E)=0,"",SUMIF(仕訳帳!J:J,G15,仕訳帳!H:H)-SUMIF(仕訳帳!I:I,G15,仕訳帳!E:E))} | M15: 略
A16: 112 | B16: 建物付属設備 | C16: =IF(B16="棚卸資産",IF(ISNUMBER(MATCH("期首商品（製品)棚卸高",仕訳帳!$I:$I,0)),INDEX(仕訳帳!$E:$E,MATCH("期首商品（製品)棚卸高",仕訳帳!$I:$I,0)),""),IF(SUMPRODUCT((ISNUMBER(仕訳帳!$C$4:$C$999))*(MONTH(仕訳帳!$C$4:$C$999)=1)*(DAY(仕訳帳!$C$4:$C$999)=1)*(仕訳帳!$I$4:$I$999=B16)*(仕訳帳!$J$4:$J$999<>"売上（収入）")*(ISNUMBER(仕訳帳!$E$4:$E$999)))=0,"",SUMPRODUCT((ISNUMBER(仕訳帳!$C$4:$C$999))*(MONTH(仕訳帳!$C$4:$C$999)=1)*(DAY(仕訳帳!$C$4:$C$999)=1)*(仕訳帳!$I$4:$I$999=B16)*(仕訳帳!$J$4:$J$999<>"売上（収入）")*(ISNUMBER(仕訳帳!$E$4:$E$999))*(仕訳帳!$E$4:$E$999)))) | D16: {=IF(B16="棚卸資産",IF(SUMIF(仕訳帳!J:J,"期末商品（製品)棚卸高",仕訳帳!H:H)=0,"",SUMIF(仕訳帳!J:J,"期末商品（製品)棚卸高",仕訳帳!H:H)),IF(SUMIF(仕訳帳!I:I,B16,仕訳帳!E:E)-SUMIF(仕訳帳!J:J,B16,仕訳帳!H:H)=0,"",SUMIF(仕訳帳!I:I,B16,仕訳帳!E:E)-SUMIF(仕訳帳!J:J,B16,仕訳帳!H:H)))} | H16: =IF(SUMPRODUCT((ISNUMBER(仕訳帳!$C$4:$C$999))*(MONTH(仕訳帳!$C$4:$C$999)=1)*(DAY(仕訳帳!$C$4:$C$999)=1)*(仕訳帳!$J$4:$J$999=G16)*(ISNUMBER(仕訳帳!$H$4:$H$999)))=0,"",SUMPRODUCT((ISNUMBER(仕訳帳!$C$4:$C$999))*(MONTH(仕訳帳!$C$4:$C$999)=1)*(DAY(仕訳帳!$C$4:$C$999)=1)*(仕訳帳!$J$4:$J$999=G16)*(ISNUMBER(仕訳帳!$H$4:$H$999))*(仕訳帳!$H$4:$H$999))) | I16: {=IF(SUMIF(仕訳帳!J:J,G16,仕訳帳!H:H)-SUMIF(仕訳帳!I:I,G16,仕訳帳!E:E)=0,"",SUMIF(仕訳帳!J:J,G16,仕訳帳!H:H)-SUMIF(仕訳帳!I:I,G16,仕訳帳!E:E))}
A17: 113 | B17: 機械装置 | C17: =IF(B17="棚卸資産",IF(ISNUMBER(MATCH("期首商品（製品)棚卸高",仕訳帳!$I:$I,0)),INDEX(仕訳帳!$E:$E,MATCH("期首商品（製品)棚卸高",仕訳帳!$I:$I,0)),""),IF(SUMPRODUCT((ISNUMBER(仕訳帳!$C$4:$C$999))*(MONTH(仕訳帳!$C$4:$C$999)=1)*(DAY(仕訳帳!$C$4:$C$999)=1)*(仕訳帳!$I$4:$I$999=B17)*(仕訳帳!$J$4:$J$999<>"売上（収入）")*(ISNUMBER(仕訳帳!$E$4:$E$999)))=0,"",SUMPRODUCT((ISNUMBER(仕訳帳!$C$4:$C$999))*(MONTH(仕訳帳!$C$4:$C$999)=1)*(DAY(仕訳帳!$C$4:$C$999)=1)*(仕訳帳!$I$4:$I$999=B17)*(仕訳帳!$J$4:$J$999<>"売上（収入）")*(ISNUMBER(仕訳帳!$E$4:$E$999))*(仕訳帳!$E$4:$E$999)))) | D17: {=IF(B17="棚卸資産",IF(SUMIF(仕訳帳!J:J,"期末商品（製品)棚卸高",仕訳帳!H:H)=0,"",SUMIF(仕訳帳!J:J,"期末商品（製品)棚卸高",仕訳帳!H:H)),IF(SUMIF(仕訳帳!I:I,B17,仕訳帳!E:E)-SUMIF(仕訳帳!J:J,B17,仕訳帳!H:H)=0,"",SUMIF(仕訳帳!I:I,B17,仕訳帳!E:E)-SUMIF(仕訳帳!J:J,B17,仕訳帳!H:H)))} | H17: =IF(SUMPRODUCT((ISNUMBER(仕訳帳!$C$4:$C$999))*(MONTH(仕訳帳!$C$4:$C$999)=1)*(DAY(仕訳帳!$C$4:$C$999)=1)*(仕訳帳!$J$4:$J$999=G17)*(ISNUMBER(仕訳帳!$H$4:$H$999)))=0,"",SUMPRODUCT((ISNUMBER(仕訳帳!$C$4:$C$999))*(MONTH(仕訳帳!$C$4:$C$999)=1)*(DAY(仕訳帳!$C$4:$C$999)=1)*(仕訳帳!$J$4:$J$999=G17)*(ISNUMBER(仕訳帳!$H$4:$H$999))*(仕訳帳!$H$4:$H$999))) | I17: {=IF(SUMIF(仕訳帳!J:J,G17,仕訳帳!H:H)-SUMIF(仕訳帳!I:I,G17,仕訳帳!E:E)=0,"",SUMIF(仕訳帳!J:J,G17,仕訳帳!H:H)-SUMIF(仕訳帳!I:I,G17,仕訳帳!E:E))}
A18: 114 | B18: 車両運搬具 | C18: =IF(B18="棚卸資産",IF(ISNUMBER(MATCH("期首商品（製品)棚卸高",仕訳帳!$I:$I,0)),INDEX(仕訳帳!$E:$E,MATCH("期首商品（製品)棚卸高",仕訳帳!$I:$I,0)),""),IF(SUMPRODUCT((ISNUMBER(仕訳帳!$C$4:$C$999))*(MONTH(仕訳帳!$C$4:$C$999)=1)*(DAY(仕訳帳!$C$4:$C$999)=1)*(仕訳帳!$I$4:$I$999=B18)*(仕訳帳!$J$4:$J$999<>"売上（収入）")*(ISNUMBER(仕訳帳!$E$4:$E$999)))=0,"",SUMPRODUCT((ISNUMBER(仕訳帳!$C$4:$C$999))*(MONTH(仕訳帳!$C$4:$C$999)=1)*(DAY(仕訳帳!$C$4:$C$999)=1)*(仕訳帳!$I$4:$I$999=B18)*(仕訳帳!$J$4:$J$999<>"売上（収入）")*(ISNUMBER(仕訳帳!$E$4:$E$999))*(仕訳帳!$E$4:$E$999)))) | D18: {=IF(B18="棚卸資産",IF(SUMIF(仕訳帳!J:J,"期末商品（製品)棚卸高",仕訳帳!H:H)=0,"",SUMIF(仕訳帳!J:J,"期末商品（製品)棚卸高",仕訳帳!H:H)),IF(SUMIF(仕訳帳!I:I,B18,仕訳帳!E:E)-SUMIF(仕訳帳!J:J,B18,仕訳帳!H:H)=0,"",SUMIF(仕訳帳!I:I,B18,仕訳帳!E:E)-SUMIF(仕訳帳!J:J,B18,仕訳帳!H:H)))} | F18: 164 | G18: 貸倒引当金 | H18: =IF(SUMPRODUCT((ISNUMBER(仕訳帳!$C$4:$C$999))*(MONTH(仕訳帳!$C$4:$C$999)=1)*(DAY(仕訳帳!$C$4:$C$999)=1)*(仕訳帳!$J$4:$J$999=G18)*(ISNUMBER(仕訳帳!$H$4:$H$999)))=0,"",SUMPRODUCT((ISNUMBER(仕訳帳!$C$4:$C$999))*(MONTH(仕訳帳!$C$4:$C$999)=1)*(DAY(仕訳帳!$C$4:$C$999)=1)*(仕訳帳!$J$4:$J$999=G18)*(ISNUMBER(仕訳帳!$H$4:$H$999))*(仕訳帳!$H$4:$H$999))) | I18: {=IF(SUMIF(仕訳帳!J:J,G18,仕訳帳!H:H)-SUMIF(仕訳帳!I:I,G18,仕訳帳!E:E)=0,"",SUMIF(仕訳帳!J:J,G18,仕訳帳!H:H)-SUMIF(仕訳帳!I:I,G18,仕訳帳!E:E))}
A19: 115 | B19: 工具 器具 備品 | C19: =IF(B19="棚卸資産",IF(ISNUMBER(MATCH("期首商品（製品)棚卸高",仕訳帳!$I:$I,0)),INDEX(仕訳帳!$E:$E,MATCH("期首商品（製品)棚卸高",仕訳帳!$I:$I,0)),""),IF(SUMPRODUCT((ISNUMBER(仕訳帳!$C$4:$C$999))*(MONTH(仕訳帳!$C$4:$C$999)=1)*(DAY(仕訳帳!$C$4:$C$999)=1)*(仕訳帳!$I$4:$I$999=B19)*(仕訳帳!$J$4:$J$999<>"売上（収入）")*(ISNUMBER(仕訳帳!$E$4:$E$999)))=0,"",SUMPRODUCT((ISNUMBER(仕訳帳!$C$4:$C$999))*(MONTH(仕訳帳!$C$4:$C$999)=1)*(DAY(仕訳帳!$C$4:$C$999)=1)*(仕訳帳!$I$4:$I$999=B19)*(仕訳帳!$J$4:$J$999<>"売上（収入）")*(ISNUMBER(仕訳帳!$E$4:$E$999))*(仕訳帳!$E$4:$E$999)))) | D19: {=IF(B19="棚卸資産",IF(SUMIF(仕訳帳!J:J,"期末商品（製品)棚卸高",仕訳帳!H:H)=0,"",SUMIF(仕訳帳!J:J,"期末商品（製品)棚卸高",仕訳帳!H:H)),IF(SUMIF(仕訳帳!I:I,B19,仕訳帳!E:E)-SUMIF(仕訳帳!J:J,B19,仕訳帳!H:H)=0,"",SUMIF(仕訳帳!I:I,B19,仕訳帳!E:E)-SUMIF(仕訳帳!J:J,B19,仕訳帳!H:H)))} | H19: =IF(SUMPRODUCT((ISNUMBER(仕訳帳!$C$4:$C$999))*(MONTH(仕訳帳!$C$4:$C$999)=1)*(DAY(仕訳帳!$C$4:$C$999)=1)*(仕訳帳!$J$4:$J$999=G19)*(ISNUMBER(仕訳帳!$H$4:$H$999)))=0,"",SUMPRODUCT((ISNUMBER(仕訳帳!$C$4:$C$999))*(MONTH(仕訳帳!$C$4:$C$999)=1)*(DAY(仕訳帳!$C$4:$C$999)=1)*(仕訳帳!$J$4:$J$999=G19)*(ISNUMBER(仕訳帳!$H$4:$H$999))*(仕訳帳!$H$4:$H$999))) | I19: {=IF(SUMIF(仕訳帳!J:J,G19,仕訳帳!H:H)-SUMIF(仕訳帳!I:I,G19,仕訳帳!E:E)=0,"",SUMIF(仕訳帳!J:J,G19,仕訳帳!H:H)-SUMIF(仕訳帳!I:I,G19,仕訳帳!E:E))}
A20: 116 | B20: 土地 | C20: =IF(B20="棚卸資産",IF(ISNUMBER(MATCH("期首商品（製品)棚卸高",仕訳帳!$I:$I,0)),INDEX(仕訳帳!$E:$E,MATCH("期首商品（製品)棚卸高",仕訳帳!$I:$I,0)),""),IF(SUMPRODUCT((ISNUMBER(仕訳帳!$C$4:$C$999))*(MONTH(仕訳帳!$C$4:$C$999)=1)*(DAY(仕訳帳!$C$4:$C$999)=1)*(仕訳帳!$I$4:$I$999=B20)*(仕訳帳!$J$4:$J$999<>"売上（収入）")*(ISNUMBER(仕訳帳!$E$4:$E$999)))=0,"",SUMPRODUCT((ISNUMBER(仕訳帳!$C$4:$C$999))*(MONTH(仕訳帳!$C$4:$C$999)=1)*(DAY(仕訳帳!$C$4:$C$999)=1)*(仕訳帳!$I$4:$I$999=B20)*(仕訳帳!$J$4:$J$999<>"売上（収入）")*(ISNUMBER(仕訳帳!$E$4:$E$999))*(仕訳帳!$E$4:$E$999)))) | D20: {=IF(B20="棚卸資産",IF(SUMIF(仕訳帳!J:J,"期末商品（製品)棚卸高",仕訳帳!H:H)=0,"",SUMIF(仕訳帳!J:J,"期末商品（製品)棚卸高",仕訳帳!H:H)),IF(SUMIF(仕訳帳!I:I,B20,仕訳帳!E:E)-SUMIF(仕訳帳!J:J,B20,仕訳帳!H:H)=0,"",SUMIF(仕訳帳!I:I,B20,仕訳帳!E:E)-SUMIF(仕訳帳!J:J,B20,仕訳帳!H:H)))} | H20: =IF(SUMPRODUCT((ISNUMBER(仕訳帳!$C$4:$C$999))*(MONTH(仕訳帳!$C$4:$C$999)=1)*(DAY(仕訳帳!$C$4:$C$999)=1)*(仕訳帳!$J$4:$J$999=G20)*(ISNUMBER(仕訳帳!$H$4:$H$999)))=0,"",SUMPRODUCT((ISNUMBER(仕訳帳!$C$4:$C$999))*(MONTH(仕訳帳!$C$4:$C$999)=1)*(DAY(仕訳帳!$C$4:$C$999)=1)*(仕訳帳!$J$4:$J$999=G20)*(ISNUMBER(仕訳帳!$H$4:$H$999))*(仕訳帳!$H$4:$H$999))) | I20: {=IF(SUMIF(仕訳帳!J:J,G20,仕訳帳!H:H)-SUMIF(仕訳帳!I:I,G20,仕訳帳!E:E)=0,"",SUMIF(仕訳帳!J:J,G20,仕訳帳!H:H)-SUMIF(仕訳帳!I:I,G20,仕訳帳!E:E))}
C21: =IF(B21="棚卸資産",IF(ISNUMBER(MATCH("期首商品（製品)棚卸高",仕訳帳!$I:$I,0)),INDEX(仕訳帳!$E:$E,MATCH("期首商品（製品)棚卸高",仕訳帳!$I:$I,0)),""),IF(SUMPRODUCT((ISNUMBER(仕訳帳!$C$4:$C$999))*(MONTH(仕訳帳!$C$4:$C$999)=1)*(DAY(仕訳帳!$C$4:$C$999)=1)*(仕訳帳!$I$4:$I$999=B21)*(仕訳帳!$J$4:$J$999<>"売上（収入）")*(ISNUMBER(仕訳帳!$E$4:$E$999)))=0,"",SUMPRODUCT((ISNUMBER(仕訳帳!$C$4:$C$999))*(MONTH(仕訳帳!$C$4:$C$999)=1)*(DAY(仕訳帳!$C$4:$C$999)=1)*(仕訳帳!$I$4:$I$999=B21)*(仕訳帳!$J$4:$J$999<>"売上（収入）")*(ISNUMBER(仕訳帳!$E$4:$E$999))*(仕訳帳!$E$4:$E$999)))) | D21: {=IF(B21="棚卸資産",IF(SUMIF(仕訳帳!J:J,"期末商品（製品)棚卸高",仕訳帳!H:H)=0,"",SUMIF(仕訳帳!J:J,"期末商品（製品)棚卸高",仕訳帳!H:H)),IF(SUMIF(仕訳帳!I:I,B21,仕訳帳!E:E)-SUMIF(仕訳帳!J:J,B21,仕訳帳!H:H)=0,"",SUMIF(仕訳帳!I:I,B21,仕訳帳!E:E)-SUMIF(仕訳帳!J:J,B21,仕訳帳!H:H)))} | H21: =IF(SUMPRODUCT((ISNUMBER(仕訳帳!$C$4:$C$999))*(MONTH(仕訳帳!$C$4:$C$999)=1)*(DAY(仕訳帳!$C$4:$C$999)=1)*(仕訳帳!$J$4:$J$999=G21)*(ISNUMBER(仕訳帳!$H$4:$H$999)))=0,"",SUMPRODUCT((ISNUMBER(仕訳帳!$C$4:$C$999))*(MONTH(仕訳帳!$C$4:$C$999)=1)*(DAY(仕訳帳!$C$4:$C$999)=1)*(仕訳帳!$J$4:$J$999=G21)*(ISNUMBER(仕訳帳!$H$4:$H$999))*(仕訳帳!$H$4:$H$999))) | I21: {=IF(SUMIF(仕訳帳!J:J,G21,仕訳帳!H:H)-SUMIF(仕訳帳!I:I,G21,仕訳帳!E:E)=0,"",SUMIF(仕訳帳!J:J,G21,仕訳帳!H:H)-SUMIF(仕訳帳!I:I,G21,仕訳帳!E:E))}
C22: =IF(B22="棚卸資産",IF(ISNUMBER(MATCH("期首商品（製品)棚卸高",仕訳帳!$I:$I,0)),INDEX(仕訳帳!$E:$E,MATCH("期首商品（製品)棚卸高",仕訳帳!$I:$I,0)),""),IF(SUMPRODUCT((ISNUMBER(仕訳帳!$C$4:$C$999))*(MONTH(仕訳帳!$C$4:$C$999)=1)*(DAY(仕訳帳!$C$4:$C$999)=1)*(仕訳帳!$I$4:$I$999=B22)*(仕訳帳!$J$4:$J$999<>"売上（収入）")*(ISNUMBER(仕訳帳!$E$4:$E$999)))=0,"",SUMPRODUCT((ISNUMBER(仕訳帳!$C$4:$C$999))*(MONTH(仕訳帳!$C$4:$C$999)=1)*(DAY(仕訳帳!$C$4:$C$999)=1)*(仕訳帳!$I$4:$I$999=B22)*(仕訳帳!$J$4:$J$999<>"売上（収入）")*(ISNUMBER(仕訳帳!$E$4:$E$999))*(仕訳帳!$E$4:$E$999)))) | D22: {=IF(B22="棚卸資産",IF(SUMIF(仕訳帳!J:J,"期末商品（製品)棚卸高",仕訳帳!H:H)=0,"",SUMIF(仕訳帳!J:J,"期末商品（製品)棚卸高",仕訳帳!H:H)),IF(SUMIF(仕訳帳!I:I,B22,仕訳帳!E:E)-SUMIF(仕訳帳!J:J,B22,仕訳帳!H:H)=0,"",SUMIF(仕訳帳!I:I,B22,仕訳帳!E:E)-SUMIF(仕訳帳!J:J,B22,仕訳帳!H:H)))} | H22: =IF(SUMPRODUCT((ISNUMBER(仕訳帳!$C$4:$C$999))*(MONTH(仕訳帳!$C$4:$C$999)=1)*(DAY(仕訳帳!$C$4:$C$999)=1)*(仕訳帳!$J$4:$J$999=G22)*(ISNUMBER(仕訳帳!$H$4:$H$999)))=0,"",SUMPRODUCT((ISNUMBER(仕訳帳!$C$4:$C$999))*(MONTH(仕訳帳!$C$4:$C$999)=1)*(DAY(仕訳帳!$C$4:$C$999)=1)*(仕訳帳!$J$4:$J$999=G22)*(ISNUMBER(仕訳帳!$H$4:$H$999))*(仕訳帳!$H$4:$H$999))) | I22: {=IF(SUMIF(仕訳帳!J:J,G22,仕訳帳!H:H)-SUMIF(仕訳帳!I:I,G22,仕訳帳!E:E)=0,"",SUMIF(仕訳帳!J:J,G22,仕訳帳!H:H)-SUMIF(仕訳帳!I:I,G22,仕訳帳!E:E))}
C23: =IF(B23="棚卸資産",IF(ISNUMBER(MATCH("期首商品（製品)棚卸高",仕訳帳!$I:$I,0)),INDEX(仕訳帳!$E:$E,MATCH("期首商品（製品)棚卸高",仕訳帳!$I:$I,0)),""),IF(SUMPRODUCT((ISNUMBER(仕訳帳!$C$4:$C$999))*(MONTH(仕訳帳!$C$4:$C$999)=1)*(DAY(仕訳帳!$C$4:$C$999)=1)*(仕訳帳!$I$4:$I$999=B23)*(仕訳帳!$J$4:$J$999<>"売上（収入）")*(ISNUMBER(仕訳帳!$E$4:$E$999)))=0,"",SUMPRODUCT((ISNUMBER(仕訳帳!$C$4:$C$999))*(MONTH(仕訳帳!$C$4:$C$999)=1)*(DAY(仕訳帳!$C$4:$C$999)=1)*(仕訳帳!$I$4:$I$999=B23)*(仕訳帳!$J$4:$J$999<>"売上（収入）")*(ISNUMBER(仕訳帳!$E$4:$E$999))*(仕訳帳!$E$4:$E$999)))) | D23: {=IF(B23="棚卸資産",IF(SUMIF(仕訳帳!J:J,"期末商品（製品)棚卸高",仕訳帳!H:H)=0,"",SUMIF(仕訳帳!J:J,"期末商品（製品)棚卸高",仕訳帳!H:H)),IF(SUMIF(仕訳帳!I:I,B23,仕訳帳!E:E)-SUMIF(仕訳帳!J:J,B23,仕訳帳!H:H)=0,"",SUMIF(仕訳帳!I:I,B23,仕訳帳!E:E)-SUMIF(仕訳帳!J:J,B23,仕訳帳!H:H)))} | H23: =IF(SUMPRODUCT((ISNUMBER(仕訳帳!$C$4:$C$999))*(MONTH(仕訳帳!$C$4:$C$999)=1)*(DAY(仕訳帳!$C$4:$C$999)=1)*(仕訳帳!$J$4:$J$999=G23)*(ISNUMBER(仕訳帳!$H$4:$H$999)))=0,"",SUMPRODUCT((ISNUMBER(仕訳帳!$C$4:$C$999))*(MONTH(仕訳帳!$C$4:$C$999)=1)*(DAY(仕訳帳!$C$4:$C$999)=1)*(仕訳帳!$J$4:$J$999=G23)*(ISNUMBER(仕訳帳!$H$4:$H$999))*(仕訳帳!$H$4:$H$999))) | I23: {=IF(SUMIF(仕訳帳!J:J,G23,仕訳帳!H:H)-SUMIF(仕訳帳!I:I,G23,仕訳帳!E:E)=0,"",SUMIF(仕訳帳!J:J,G23,仕訳帳!H:H)-SUMIF(仕訳帳!I:I,G23,仕訳帳!E:E))}
C24: =IF(B24="棚卸資産",IF(ISNUMBER(MATCH("期首商品（製品)棚卸高",仕訳帳!$I:$I,0)),INDEX(仕訳帳!$E:$E,MATCH("期首商品（製品)棚卸高",仕訳帳!$I:$I,0)),""),IF(SUMPRODUCT((ISNUMBER(仕訳帳!$C$4:$C$999))*(MONTH(仕訳帳!$C$4:$C$999)=1)*(DAY(仕訳帳!$C$4:$C$999)=1)*(仕訳帳!$I$4:$I$999=B24)*(仕訳帳!$J$4:$J$999<>"売上（収入）")*(ISNUMBER(仕訳帳!$E$4:$E$999)))=0,"",SUMPRODUCT((ISNUMBER(仕訳帳!$C$4:$C$999))*(MONTH(仕訳帳!$C$4:$C$999)=1)*(DAY(仕訳帳!$C$4:$C$999)=1)*(仕訳帳!$I$4:$I$999=B24)*(仕訳帳!$J$4:$J$999<>"売上（収入）")*(ISNUMBER(仕訳帳!$E$4:$E$999))*(仕訳帳!$E$4:$E$999)))) | D24: {=IF(B24="棚卸資産",IF(SUMIF(仕訳帳!J:J,"期末商品（製品)棚卸高",仕訳帳!H:H)=0,"",SUMIF(仕訳帳!J:J,"期末商品（製品)棚卸高",仕訳帳!H:H)),IF(SUMIF(仕訳帳!I:I,B24,仕訳帳!E:E)-SUMIF(仕訳帳!J:J,B24,仕訳帳!H:H)=0,"",SUMIF(仕訳帳!I:I,B24,仕訳帳!E:E)-SUMIF(仕訳帳!J:J,B24,仕訳帳!H:H)))} | H24: =IF(SUMPRODUCT((ISNUMBER(仕訳帳!$C$4:$C$999))*(MONTH(仕訳帳!$C$4:$C$999)=1)*(DAY(仕訳帳!$C$4:$C$999)=1)*(仕訳帳!$J$4:$J$999=G24)*(ISNUMBER(仕訳帳!$H$4:$H$999)))=0,"",SUMPRODUCT((ISNUMBER(仕訳帳!$C$4:$C$999))*(MONTH(仕訳帳!$C$4:$C$999)=1)*(DAY(仕訳帳!$C$4:$C$999)=1)*(仕訳帳!$J$4:$J$999=G24)*(ISNUMBER(仕訳帳!$H$4:$H$999))*(仕訳帳!$H$4:$H$999))) | I24: {=IF(SUMIF(仕訳帳!J:J,G24,仕訳帳!H:H)-SUMIF(仕訳帳!I:I,G24,仕訳帳!E:E)=0,"",SUMIF(仕訳帳!J:J,G24,仕訳帳!H:H)-SUMIF(仕訳帳!I:I,G24,仕訳帳!E:E))}
C25: =IF(B25="棚卸資産",IF(ISNUMBER(MATCH("期首商品（製品)棚卸高",仕訳帳!$I:$I,0)),INDEX(仕訳帳!$E:$E,MATCH("期首商品（製品)棚卸高",仕訳帳!$I:$I,0)),""),IF(SUMPRODUCT((ISNUMBER(仕訳帳!$C$4:$C$999))*(MONTH(仕訳帳!$C$4:$C$999)=1)*(DAY(仕訳帳!$C$4:$C$999)=1)*(仕訳帳!$I$4:$I$999=B25)*(仕訳帳!$J$4:$J$999<>"売上（収入）")*(ISNUMBER(仕訳帳!$E$4:$E$999)))=0,"",SUMPRODUCT((ISNUMBER(仕訳帳!$C$4:$C$999))*(MONTH(仕訳帳!$C$4:$C$999)=1)*(DAY(仕訳帳!$C$4:$C$999)=1)*(仕訳帳!$I$4:$I$999=B25)*(仕訳帳!$J$4:$J$999<>"売上（収入）")*(ISNUMBER(仕訳帳!$E$4:$E$999))*(仕訳帳!$E$4:$E$999)))) | D25: {=IF(B25="棚卸資産",IF(SUMIF(仕訳帳!J:J,"期末商品（製品)棚卸高",仕訳帳!H:H)=0,"",SUMIF(仕訳帳!J:J,"期末商品（製品)棚卸高",仕訳帳!H:H)),IF(SUMIF(仕訳帳!I:I,B25,仕訳帳!E:E)-SUMIF(仕訳帳!J:J,B25,仕訳帳!H:H)=0,"",SUMIF(仕訳帳!I:I,B25,仕訳帳!E:E)-SUMIF(仕訳帳!J:J,B25,仕訳帳!H:H)))} | H25: =IF(SUMPRODUCT((ISNUMBER(仕訳帳!$C$4:$C$999))*(MONTH(仕訳帳!$C$4:$C$999)=1)*(DAY(仕訳帳!$C$4:$C$999)=1)*(仕訳帳!$J$4:$J$999=G25)*(ISNUMBER(仕訳帳!$H$4:$H$999)))=0,"",SUMPRODUCT((ISNUMBER(仕訳帳!$C$4:$C$999))*(MONTH(仕訳帳!$C$4:$C$999)=1)*(DAY(仕訳帳!$C$4:$C$999)=1)*(仕訳帳!$J$4:$J$999=G25)*(ISNUMBER(仕訳帳!$H$4:$H$999))*(仕訳帳!$H$4:$H$999))) | I25: {=IF(SUMIF(仕訳帳!J:J,G25,仕訳帳!H:H)-SUMIF(仕訳帳!I:I,G25,仕訳帳!E:E)=0,"",SUMIF(仕訳帳!J:J,G25,仕訳帳!H:H)-SUMIF(仕訳帳!I:I,G25,仕訳帳!E:E))}
C26: =IF(B26="棚卸資産",IF(ISNUMBER(MATCH("期首商品（製品)棚卸高",仕訳帳!$I:$I,0)),INDEX(仕訳帳!$E:$E,MATCH("期首商品（製品)棚卸高",仕訳帳!$I:$I,0)),""),IF(SUMPRODUCT((ISNUMBER(仕訳帳!$C$4:$C$999))*(MONTH(仕訳帳!$C$4:$C$999)=1)*(DAY(仕訳帳!$C$4:$C$999)=1)*(仕訳帳!$I$4:$I$999=B26)*(仕訳帳!$J$4:$J$999<>"売上（収入）")*(ISNUMBER(仕訳帳!$E$4:$E$999)))=0,"",SUMPRODUCT((ISNUMBER(仕訳帳!$C$4:$C$999))*(MONTH(仕訳帳!$C$4:$C$999)=1)*(DAY(仕訳帳!$C$4:$C$999)=1)*(仕訳帳!$I$4:$I$999=B26)*(仕訳帳!$J$4:$J$999<>"売上（収入）")*(ISNUMBER(仕訳帳!$E$4:$E$999))*(仕訳帳!$E$4:$E$999)))) | D26: {=IF(B26="棚卸資産",IF(SUMIF(仕訳帳!J:J,"期末商品（製品)棚卸高",仕訳帳!H:H)=0,"",SUMIF(仕訳帳!J:J,"期末商品（製品)棚卸高",仕訳帳!H:H)),IF(SUMIF(仕訳帳!I:I,B26,仕訳帳!E:E)-SUMIF(仕訳帳!J:J,B26,仕訳帳!H:H)=0,"",SUMIF(仕訳帳!I:I,B26,仕訳帳!E:E)-SUMIF(仕訳帳!J:J,B26,仕訳帳!H:H)))} | F26: 172 | G26: 事業主借 | I26: {=IF(SUMIF(仕訳帳!J:J,G26,仕訳帳!H:H)-SUMIF(仕訳帳!I:I,G26,仕訳帳!E:E)=0,"",SUMIF(仕訳帳!J:J,G26,仕訳帳!H:H)-SUMIF(仕訳帳!I:I,G26,仕訳帳!E:E))}
A27: 123 | B27: 開業費 | C27: =IF(B27="棚卸資産",IF(ISNUMBER(MATCH("期首商品（製品)棚卸高",仕訳帳!$I:$I,0)),INDEX(仕訳帳!$E:$E,MATCH("期首商品（製品)棚卸高",仕訳帳!$I:$I,0)),""),IF(SUMPRODUCT((ISNUMBER(仕訳帳!$C$4:$C$999))*(MONTH(仕訳帳!$C$4:$C$999)=1)*(DAY(仕訳帳!$C$4:$C$999)=1)*(仕訳帳!$I$4:$I$999=B27)*(仕訳帳!$J$4:$J$999<>"売上（収入）")*(ISNUMBER(仕訳帳!$E$4:$E$999)))=0,"",SUMPRODUCT((ISNUMBER(仕訳帳!$C$4:$C$999))*(MONTH(仕訳帳!$C$4:$C$999)=1)*(DAY(仕訳帳!$C$4:$C$999)=1)*(仕訳帳!$I$4:$I$999=B27)*(仕訳帳!$J$4:$J$999<>"売上（収入）")*(ISNUMBER(仕訳帳!$E$4:$E$999))*(仕訳帳!$E$4:$E$999)))) | D27: {=IF(B27="棚卸資産",IF(SUMIF(仕訳帳!J:J,"期末商品（製品)棚卸高",仕訳帳!H:H)=0,"",SUMIF(仕訳帳!J:J,"期末商品（製品)棚卸高",仕訳帳!H:H)),IF(SUMIF(仕訳帳!I:I,B27,仕訳帳!E:E)-SUMIF(仕訳帳!J:J,B27,仕訳帳!H:H)=0,"",SUMIF(仕訳帳!I:I,B27,仕訳帳!E:E)-SUMIF(仕訳帳!J:J,B27,仕訳帳!H:H)))} | F27: 199 | G27: 元入金 | H27: =C29-SUM(H5:H25) -> 0 | I27: =IF(H27=0,SUMIF(仕訳帳!J:J,"元入金",仕訳帳!E:E),H27) -> 0
A28: 124 | B28: 事業主貸 | D28: {=IF(B28="棚卸資産",IF(SUMIF(仕訳帳!J:J,"期末商品（製品)棚卸高",仕訳帳!H:H)=0,"",SUMIF(仕訳帳!J:J,"期末商品（製品)棚卸高",仕訳帳!H:H)),IF(SUMIF(仕訳帳!I:I,B28,仕訳帳!E:E)-SUMIF(仕訳帳!J:J,B28,仕訳帳!H:H)=0,"",SUMIF(仕訳帳!I:I,B28,仕訳帳!E:E)-SUMIF(仕訳帳!J:J,B28,仕訳帳!H:H)))} | G28: 青色申告特別控除 前の所得金額 | I28: =IFERROR(IF('①青色申告決算書（損益計算書）'!P16<>"",'①青色申告決算書（損益計算書）'!P16,""),"") -> 0
B29: 合計 | C29: =SUM(C5:C27) -> 0 | D29: =SUM(D5:D28) -> 0 | G29: 合計 | H29: =SUM(H5:H25)+H27 -> 0 | I29: =SUM(I5:I28) -> 0

Sheet 総勘定元帳
A1: 【総勘定元帳】
C2: 勘定科目 | E2: ▼から選択できます。
B4: 日付 | C4: 仕分け番号 | D4: 借方勘定科目 | E4: 貸方金額 | F4: 貸方勘定科目 | G4: 借方金額 | H4: 残高・合計 | I4: 貸方累計 | J4: 借方累計 | K4: 摘要 | L4: メモ
B5: =IF(C5<>"",INDEX(仕訳帳!C:C,MATCH(C5,仕訳帳!B:B,0)),"") | C5: {=IF($D$2="","",IFERROR(INDEX(仕訳帳!B:B,MATCH(SMALL(IF((仕訳帳!I:I=$D$2)+(仕訳帳!J:J=$D$2),仕訳帳!C:C*10000+ROW(仕訳帳!C:C)),ROW(A1)),仕訳帳!C:C*10000+ROW(仕訳帳!C:C),0)),""))} | D5: =IF(C5<>"",IF(INDEX(仕訳帳!I:I,MATCH(C5,仕訳帳!B:B,0))=$D$2,"---",INDEX(仕訳帳!I:I,MATCH(C5,仕訳帳!B:B,0))),"") | E5: =IF(C5<>"",IF(INDEX(仕訳帳!I:I,MATCH(C5,仕訳帳!B:B,0))=$D$2,"-",INDEX(仕訳帳!E:E,MATCH(C5,仕訳帳!B:B,0))),"") | F5: =IF(C5<>"",IF(INDEX(仕訳帳!J:J,MATCH(C5,仕訳帳!B:B,0))=$D$2,"---",INDEX(仕訳帳!J:J,MATCH(C5,仕訳帳!B:B,0))),"") | G5: =IF(C5<>"",IF(INDEX(仕訳帳!J:J,MATCH(C5,仕訳帳!B:B,0))=$D$2,"-",INDEX(仕訳帳!H:H,MATCH(C5,仕訳帳!B:B,0))),"") | H5: =IF(B5="","",SUM(H4,IF(E5="-",0,-E5)+IF(G5="-",0,G5))) | I5: =IF(C5="","",IF(ROW()=5,0,I4)+IF(E5="-",0,IF(E5="",0,E5))) | J5: =IF(C5="","",IF(ROW()=5,0,J4)+IF(G5="-",0,IF(G5="",0,G5))) | K5: =IF(C5<>"",IF(INDEX(仕訳帳!F:F,MATCH(C5,仕訳帳!B:B,0))="","",INDEX(仕訳帳!F:F,MATCH(C5,仕訳帳!B:B,0))),"") | L5: =IF(C5<>"",IF(INDEX(仕訳帳!K:K,MATCH(C5,仕訳帳!B:B,0))="","",INDEX(仕訳帳!K:K,MATCH(C5,仕訳帳!B:B,0))),"")
B6: =IF(C6<>"",INDEX(仕訳帳!C:C,MATCH(C6,仕訳帳!B:B,0)),"") | C6: {=IF($D$2="","",IFERROR(INDEX(仕訳帳!B:B,MATCH(SMALL(IF((仕訳帳!I:I=$D$2)+(仕訳帳!J:J=$D$2),仕訳帳!C:C*10000+ROW(仕訳帳!C:C)),ROW(A2)),仕訳帳!C:C*10000+ROW(仕訳帳!C:C),0)),""))} | D6: =IF(C6<>"",IF(INDEX(仕訳帳!I:I,MATCH(C6,仕訳帳!B:B,0))=$D$2,"---",INDEX(仕訳帳!I:I,MATCH(C6,仕訳帳!B:B,0))),"") | E6: =IF(C6<>"",IF(INDEX(仕訳帳!I:I,MATCH(C6,仕訳帳!B:B,0))=$D$2,"-",INDEX(仕訳帳!E:E,MATCH(C6,仕訳帳!B:B,0))),"") | F6: =IF(C6<>"",IF(INDEX(仕訳帳!J:J,MATCH(C6,仕訳帳!B:B,0))=$D$2,"---",INDEX(仕訳帳!J:J,MATCH(C6,仕訳帳!B:B,0))),"") | G6: =IF(C6<>"",IF(INDEX(仕訳帳!J:J,MATCH(C6,仕訳帳!B:B,0))=$D$2,"-",INDEX(仕訳帳!H:H,MATCH(C6,仕訳帳!B:B,0))),"") | H6: =IF(B6="","",SUM(H5,IF(E6="-",0,-E6)+IF(G6="-",0,G6))) | I6: =IF(C6="","",IF(ROW()=5,0,I5)+IF(E6="-",0,IF(E6="",0,E6))) | J6: =IF(C6="","",IF(ROW()=5,0,J5)+IF(G6="-",0,IF(G6="",0,G6))) | K6: =IF(C6<>"",IF(INDEX(仕訳帳!F:F,MATCH(C6,仕訳帳!B:B,0))="","",INDEX(仕訳帳!F:F,MATCH(C6,仕訳帳!B:B,0))),"") | L6: =IF(C6<>"",IF(INDEX(仕訳帳!K:K,MATCH(C6,仕訳帳!B:B,0))="","",INDEX(仕訳帳!K:K,MATCH(C6,仕訳帳!B:B,0))),"")
B7: =IF(C7<>"",INDEX(仕訳帳!C:C,MATCH(C7,仕訳帳!B:B,0)),"") | C7: {=IF($D$2="","",IFERROR(INDEX(仕訳帳!B:B,MATCH(SMALL(IF((仕訳帳!I:I=$D$2)+(仕訳帳!J:J=$D$2),仕訳帳!C:C*10000+ROW(仕訳帳!C:C)),ROW(A3)),仕訳帳!C:C*10000+ROW(仕訳帳!C:C),0)),""))} | D7: =IF(C7<>"",IF(INDEX(仕訳帳!I:I,MATCH(C7,仕訳帳!B:B,0))=$D$2,"---",INDEX(仕訳帳!I:I,MATCH(C7,仕訳帳!B:B,0))),"") | E7: =IF(C7<>"",IF(INDEX(仕訳帳!I:I,MATCH(C7,仕訳帳!B:B,0))=$D$2,"-",INDEX(仕訳帳!E:E,MATCH(C7,仕訳帳!B:B,0))),"") | F7: =IF(C7<>"",IF(INDEX(仕訳帳!J:J,MATCH(C7,仕訳帳!B:B,0))=$D$2,"---",INDEX(仕訳帳!J:J,MATCH(C7,仕訳帳!B:B,0))),"") | G7: =IF(C7<>"",IF(INDEX(仕訳帳!J:J,MATCH(C7,仕訳帳!B:B,0))=$D$2,"-",INDEX(仕訳帳!H:H,MATCH(C7,仕訳帳!B:B,0))),"") | H7: =IF(B7="","",SUM(H6,IF(E7="-",0,-E7)+IF(G7="-",0,G7))) | I7: =IF(C7="","",IF(ROW()=5,0,I6)+IF(E7="-",0,IF(E7="",0,E7))) | J7: =IF(C7="","",IF(ROW()=5,0,J6)+IF(G7="-",0,IF(G7="",0,G7))) | K7: =IF(C7<>"",IF(INDEX(仕訳帳!F:F,MATCH(C7,仕訳帳!B:B,0))="","",INDEX(仕訳帳!F:F,MATCH(C7,仕訳帳!B:B,0))),"") | L7: =IF(C7<>"",IF(INDEX(仕訳帳!K:K,MATCH(C7,仕訳帳!B:B,0))="","",INDEX(仕訳帳!K:K,MATCH(C7,仕訳帳!B:B,0))),"")
B8: =IF(C8<>"",INDEX(仕訳帳!C:C,MATCH(C8,仕訳帳!B:B,0)),"") | C8: {=IF($D$2="","",IFERROR(INDEX(仕訳帳!B:B,MATCH(SMALL(IF((仕訳帳!I:I=$D$2)+(仕訳帳!J:J=$D$2),仕訳帳!C:C*10000+ROW(仕訳帳!C:C)),ROW(A4)),仕訳帳!C:C*10000+ROW(仕訳帳!C:C),0)),""))} | D8: =IF(C8<>"",IF(INDEX(仕訳帳!I:I,MATCH(C8,仕訳帳!B:B,0))=$D$2,"---",INDEX(仕訳帳!I:I,MATCH(C8,仕訳帳!B:B,0))),"") | E8: =IF(C8<>"",IF(INDEX(仕訳帳!I:I,MATCH(C8,仕訳帳!B:B,0))=$D$2,"-",INDEX(仕訳帳!E:E,MATCH(C8,仕訳帳!B:B,0))),"") | F8: =IF(C8<>"",IF(INDEX(仕訳帳!J:J,MATCH(C8,仕訳帳!B:B,0))=$D$2,"---",INDEX(仕訳帳!J:J,MATCH(C8,仕訳帳!B:B,0))),"") | G8: =IF(C8<>"",IF(INDEX(仕訳帳!J:J,MATCH(C8,仕訳帳!B:B,0))=$D$2,"-",INDEX(仕訳帳!H:H,MATCH(C8,仕訳帳!B:B,0))),"") | H8: =IF(B8="","",SUM(H7,IF(E8="-",0,-E8)+IF(G8="-",0,G8))) | I8: =IF(C8="","",IF(ROW()=5,0,I7)+IF(E8="-",0,IF(E8="",0,E8))) | J8: =IF(C8="","",IF(ROW()=5,0,J7)+IF(G8="-",0,IF(G8="",0,G8))) | K8: =IF(C8<>"",IF(INDEX(仕訳帳!F:F,MATCH(C8,仕訳帳!B:B,0))="","",INDEX(仕訳帳!F:F,MATCH(C8,仕訳帳!B:B,0))),"") | L8: =IF(C8<>"",IF(INDEX(仕訳帳!K:K,MATCH(C8,仕訳帳!B:B,0))="","",INDEX(仕訳帳!K:K,MATCH(C8,仕訳帳!B:B,0))),"")
B9: =IF(C9<>"",INDEX(仕訳帳!C:C,MATCH(C9,仕訳帳!B:B,0)),"") | C9: {=IF($D$2="","",IFERROR(INDEX(仕訳帳!B:B,MATCH(SMALL(IF((仕訳帳!I:I=$D$2)+(仕訳帳!J:J=$D$2),仕訳帳!C:C*10000+ROW(仕訳帳!C:C)),ROW(A5)),仕訳帳!C:C*10000+ROW(仕訳帳!C:C),0)),""))} | D9: =IF(C9<>"",IF(INDEX(仕訳帳!I:I,MATCH(C9,仕訳帳!B:B,0))=$D$2,"---",INDEX(仕訳帳!I:I,MATCH(C9,仕訳帳!B:B,0))),"") | E9: =IF(C9<>"",IF(INDEX(仕訳帳!I:I,MATCH(C9,仕訳帳!B:B,0))=$D$2,"-",INDEX(仕訳帳!E:E,MATCH(C9,仕訳帳!B:B,0))),"") | F9: =IF(C9<>"",IF(INDEX(仕訳帳!J:J,MATCH(C9,仕訳帳!B:B,0))=$D$2,"---",INDEX(仕訳帳!J:J,MATCH(C9,仕訳帳!B:B,0))),"") | G9: =IF(C9<>"",IF(INDEX(仕訳帳!J:J,MATCH(C9,仕訳帳!B:B,0))=$D$2,"-",INDEX(仕訳帳!H:H,MATCH(C9,仕訳帳!B:B,0))),"") | H9: =IF(B9="","",SUM(H8,IF(E9="-",0,-E9)+IF(G9="-",0,G9))) | I9: =IF(C9="","",IF(ROW()=5,0,I8)+IF(E9="-",0,IF(E9="",0,E9))) | J9: =IF(C9="","",IF(ROW()=5,0,J8)+IF(G9="-",0,IF(G9="",0,G9))) | K9: =IF(C9<>"",IF(INDEX(仕訳帳!F:F,MATCH(C9,仕訳帳!B:B,0))="","",INDEX(仕訳帳!F:F,MATCH(C9,仕訳帳!B:B,0))),"") | L9: =IF(C9<>"",IF(INDEX(仕訳帳!K:K,MATCH(C9,仕訳帳!B:B,0))="","",INDEX(仕訳帳!K:K,MATCH(C9,仕訳帳!B:B,0))),"")
B10: =IF(C10<>"",INDEX(仕訳帳!C:C,MATCH(C10,仕訳帳!B:B,0)),"") | C10: {=IF($D$2="","",IFERROR(INDEX(仕訳帳!B:B,MATCH(SMALL(IF((仕訳帳!I:I=$D$2)+(仕訳帳!J:J=$D$2),仕訳帳!C:C*10000+ROW(仕訳帳!C:C)),ROW(A6)),仕訳帳!C:C*10000+ROW(仕訳帳!C:C),0)),""))} | D10: =IF(C10<>"",IF(INDEX(仕訳帳!I:I,MATCH(C10,仕訳帳!B:B,0))=$D$2,"---",INDEX(仕訳帳!I:I,MATCH(C10,仕訳帳!B:B,0))),"") | E10: =IF(C10<>"",IF(INDEX(仕訳帳!I:I,MATCH(C10,仕訳帳!B:B,0))=$D$2,"-",INDEX(仕訳帳!E:E,MATCH(C10,仕訳帳!B:B,0))),"") | F10: =IF(C10<>"",IF(INDEX(仕訳帳!J:J,MATCH(C10,仕訳帳!B:B,0))=$D$2,"---",INDEX(仕訳帳!J:J,MATCH(C10,仕訳帳!B:B,0))),"") | G10: =IF(C10<>"",IF(INDEX(仕訳帳!J:J,MATCH(C10,仕訳帳!B:B,0))=$D$2,"-",INDEX(仕訳帳!H:H,MATCH(C10,仕訳帳!B:B,0))),"") | H10: =IF(B10="","",SUM(H9,IF(E10="-",0,-E10)+IF(G10="-",0,G10))) | I10: =IF(C10="","",IF(ROW()=5,0,I9)+IF(E10="-",0,IF(E10="",0,E10))) | J10: =IF(C10="","",IF(ROW()=5,0,J9)+IF(G10="-",0,IF(G10="",0,G10))) | K10: =IF(C10<>"",IF(INDEX(仕訳帳!F:F,MATCH(C10,仕訳帳!B:B,0))="","",INDEX(仕訳帳!F:F,MATCH(C10,仕訳帳!B:B,0))),"") | L10: =IF(C10<>"",IF(INDEX(仕訳帳!K:K,MATCH(C10,仕訳帳!B:B,0))="","",INDEX(仕訳帳!K:K,MATCH(C10,仕訳帳!B:B,0))),"")
B11: =IF(C11<>"",INDEX(仕訳帳!C:C,MATCH(C11,仕訳帳!B:B,0)),"") | C11: {=IF($D$2="","",IFERROR(INDEX(仕訳帳!B:B,MATCH(SMALL(IF((仕訳帳!I:I=$D$2)+(仕訳帳!J:J=$D$2),仕訳帳!C:C*10000+ROW(仕訳帳!C:C)),ROW(A7)),仕訳帳!C:C*10000+ROW(仕訳帳!C:C),0)),""))} | D11: =IF(C11<>"",IF(INDEX(仕訳帳!I:I,MATCH(C11,仕訳帳!B:B,0))=$D$2,"---",INDEX(仕訳帳!I:I,MATCH(C11,仕訳帳!B:B,0))),"") | E11: =IF(C11<>"",IF(INDEX(仕訳帳!I:I,MATCH(C11,仕訳帳!B:B,0))=$D$2,"-",INDEX(仕訳帳!E:E,MATCH(C11,仕訳帳!B:B,0))),"") | F11: =IF(C11<>"",IF(INDEX(仕訳帳!J:J,MATCH(C11,仕訳帳!B:B,0))=$D$2,"---",INDEX(仕訳帳!J:J,MATCH(C11,仕訳帳!B:B,0))),"") | G11: =IF(C11<>"",IF(INDEX(仕訳帳!J:J,MATCH(C11,仕訳帳!B:B,0))=$D$2,"-",INDEX(仕訳帳!H:H,MATCH(C11,仕訳帳!B:B,0))),"") | H11: =IF(B11="","",SUM(H10,IF(E11="-",0,-E11)+IF(G11="-",0,G11))) | I11: =IF(C11="","",IF(ROW()=5,0,I10)+IF(E11="-",0,IF(E11="",0,E11))) | J11: =IF(C11="","",IF(ROW()=5,0,J10)+IF(G11="-",0,IF(G11="",0,G11))) | K11: =IF(C11<>"",IF(INDEX(仕訳帳!F:F,MATCH(C11,仕訳帳!B:B,0))="","",INDEX(仕訳帳!F:F,MATCH(C11,仕訳帳!B:B,0))),"") | L11: =IF(C11<>"",IF(INDEX(仕訳帳!K:K,MATCH(C11,仕訳帳!B:B,0))="","",INDEX(仕訳帳!K:K,MATCH(C11,仕訳帳!B:B,0))),"")
B12: =IF(C12<>"",INDEX(仕訳帳!C:C,MATCH(C12,仕訳帳!B:B,0)),"") | C12: {=IF($D$2="","",IFERROR(INDEX(仕訳帳!B:B,MATCH(SMALL(IF((仕訳帳!I:I=$D$2)+(仕訳帳!J:J=$D$2),仕訳帳!C:C*10000+ROW(仕訳帳!C:C)),ROW(A8)),仕訳帳!C:C*10000+ROW(仕訳帳!C:C),0)),""))} | D12: =IF(C12<>"",IF(INDEX(仕訳帳!I:I,MATCH(C12,仕訳帳!B:B,0))=$D$2,"---",INDEX(仕訳帳!I:I,MATCH(C12,仕訳帳!B:B,0))),"") | E12: =IF(C12<>"",IF(INDEX(仕訳帳!I:I,MATCH(C12,仕訳帳!B:B,0))=$D$2,"-",INDEX(仕訳帳!E:E,MATCH(C12,仕訳帳!B:B,0))),"") | F12: =IF(C12<>"",IF(INDEX(仕訳帳!J:J,MATCH(C12,仕訳帳!B:B,0))=$D$2,"---",INDEX(仕訳帳!J:J,MATCH(C12,仕訳帳!B:B,0))),"") | G12: =IF(C12<>"",IF(INDEX(仕訳帳!J:J,MATCH(C12,仕訳帳!B:B,0))=$D$2,"-",INDEX(仕訳帳!H:H,MATCH(C12,仕訳帳!B:B,0))),"") | H12: =IF(B12="","",SUM(H11,IF(E12="-",0,-E12)+IF(G12="-",0,G12))) | I12: =IF(C12="","",IF(ROW()=5,0,I11)+IF(E12="-",0,IF(E12="",0,E12))) | J12: =IF(C12="","",IF(ROW()=5,0,J11)+IF(G12="-",0,IF(G12="",0,G12))) | K12: =IF(C12<>"",IF(INDEX(仕訳帳!F:F,MATCH(C12,仕訳帳!B:B,0))="","",INDEX(仕訳帳!F:F,MATCH(C12,仕訳帳!B:B,0))),"") | L12: =IF(C12<>"",IF(INDEX(仕訳帳!K:K,MATCH(C12,仕訳帳!B:B,0))="","",INDEX(仕訳帳!K:K,MATCH(C12,仕訳帳!B:B,0))),"")
B13: =IF(C13<>"",INDEX(仕訳帳!C:C,MATCH(C13,仕訳帳!B:B,0)),"") | C13: {=IF($D$2="","",IFERROR(INDEX(仕訳帳!B:B,MATCH(SMALL(IF((仕訳帳!I:I=$D$2)+(仕訳帳!J:J=$D$2),仕訳帳!C:C*10000+ROW(仕訳帳!C:C)),ROW(A9)),仕訳帳!C:C*10000+ROW(仕訳帳!C:C),0)),""))} | D13: =IF(C13<>"",IF(INDEX(仕訳帳!I:I,MATCH(C13,仕訳帳!B:B,0))=$D$2,"---",INDEX(仕訳帳!I:I,MATCH(C13,仕訳帳!B:B,0))),"") | E13: =IF(C13<>"",IF(INDEX(仕訳帳!I:I,MATCH(C13,仕訳帳!B:B,0))=$D$2,"-",INDEX(仕訳帳!E:E,MATCH(C13,仕訳帳!B:B,0))),"") | F13: =IF(C13<>"",IF(INDEX(仕訳帳!J:J,MATCH(C13,仕訳帳!B:B,0))=$D$2,"---",INDEX(仕訳帳!J:J,MATCH(C13,仕訳帳!B:B,0))),"") | G13: =IF(C13<>"",IF(INDEX(仕訳帳!J:J,MATCH(C13,仕訳帳!B:B,0))=$D$2,"-",INDEX(仕訳帳!H:H,MATCH(C13,仕訳帳!B:B,0))),"") | H13: =IF(B13="","",SUM(H12,IF(E13="-",0,-E13)+IF(G13="-",0,G13))) | I13: =IF(C13="","",IF(ROW()=5,0,I12)+IF(E13="-",0,IF(E13="",0,E13))) | J13: =IF(C13="","",IF(ROW()=5,0,J12)+IF(G13="-",0,IF(G13="",0,G13))) | K13: =IF(C13<>"",IF(INDEX(仕訳帳!F:F,MATCH(C13,仕訳帳!B:B,0))="","",INDEX(仕訳帳!F:F,MATCH(C13,仕訳帳!B:B,0))),"") | L13: =IF(C13<>"",IF(INDEX(仕訳帳!K:K,MATCH(C13,仕訳帳!B:B,0))="","",INDEX(仕訳帳!K:K,MATCH(C13,仕訳帳!B:B,0))),"")
B14: =IF(C14<>"",INDEX(仕訳帳!C:C,MATCH(C14,仕訳帳!B:B,0)),"") | C14: {=IF($D$2="","",IFERROR(INDEX(仕訳帳!B:B,MATCH(SMALL(IF((仕訳帳!I:I=$D$2)+(仕訳帳!J:J=$D$2),仕訳帳!C:C*10000+ROW(仕訳帳!C:C)),ROW(A10)),仕訳帳!C:C*10000+ROW(仕訳帳!C:C),0)),""))} | D14: =IF(C14<>"",IF(INDEX(仕訳帳!I:I,MATCH(C14,仕訳帳!B:B,0))=$D$2,"---",INDEX(仕訳帳!I:I,MATCH(C14,仕訳帳!B:B,0))),"") | E14: =IF(C14<>"",IF(INDEX(仕訳帳!I:I,MATCH(C14,仕訳帳!B:B,0))=$D$2,"-",INDEX(仕訳帳!E:E,MATCH(C14,仕訳帳!B:B,0))),"") | F14: =IF(C14<>"",IF(INDEX(仕訳帳!J:J,MATCH(C14,仕訳帳!B:B,0))=$D$2,"---",INDEX(仕訳帳!J:J,MATCH(C14,仕訳帳!B:B,0))),"") | G14: =IF(C14<>"",IF(INDEX(仕訳帳!J:J,MATCH(C14,仕訳帳!B:B,0))=$D$2,"-",INDEX(仕訳帳!H:H,MATCH(C14,仕訳帳!B:B,0))),"") | H14: =IF(B14="","",SUM(H13,IF(E14="-",0,-E14)+IF(G14="-",0,G14))) | I14: =IF(C14="","",IF(ROW()=5,0,I13)+IF(E14="-",0,IF(E14="",0,E14))) | J14: =IF(C14="","",IF(ROW()=5,0,J13)+IF(G14="-",0,IF(G14="",0,G14))) | K14: =IF(C14<>"",IF(INDEX(仕訳帳!F:F,MATCH(C14,仕訳帳!B:B,0))="","",INDEX(仕訳帳!F:F,MATCH(C14,仕訳帳!B:B,0))),"") | L14: =IF(C14<>"",IF(INDEX(仕訳帳!K:K,MATCH(C14,仕訳帳!B:B,0))="","",INDEX(仕訳帳!K:K,MATCH(C14,仕訳帳!B:B,0))),"")
B15: =IF(C15<>"",INDEX(仕訳帳!C:C,MATCH(C15,仕訳帳!B:B,0)),"") | C15: {=IF($D$2="","",IFERROR(INDEX(仕訳帳!B:B,MATCH(SMALL(IF((仕訳帳!I:I=$D$2)+(仕訳帳!J:J=$D$2),仕訳帳!C:C*10000+ROW(仕訳帳!C:C)),ROW(A11)),仕訳帳!C:C*10000+ROW(仕訳帳!C:C),0)),""))} | D15: =IF(C15<>"",IF(INDEX(仕訳帳!I:I,MATCH(C15,仕訳帳!B:B,0))=$D$2,"---",INDEX(仕訳帳!I:I,MATCH(C15,仕訳帳!B:B,0))),"") | E15: =IF(C15<>"",IF(INDEX(仕訳帳!I:I,MATCH(C15,仕訳帳!B:B,0))=$D$2,"-",INDEX(仕訳帳!E:E,MATCH(C15,仕訳帳!B:B,0))),"") | F15: =IF(C15<>"",IF(INDEX(仕訳帳!J:J,MATCH(C15,仕訳帳!B:B,0))=$D$2,"---",INDEX(仕訳帳!J:J,MATCH(C15,仕訳帳!B:B,0))),"") | G15: =IF(C15<>"",IF(INDEX(仕訳帳!J:J,MATCH(C15,仕訳帳!B:B,0))=$D$2,"-",INDEX(仕訳帳!H:H,MATCH(C15,仕訳帳!B:B,0))),"") | H15: =IF(B15="","",SUM(H14,IF(E15="-",0,-E15)+IF(G15="-",0,G15))) | I15: =IF(C15="","",IF(ROW()=5,0,I14)+IF(E15="-",0,IF(E15="",0,E15))) | J15: =IF(C15="","",IF(ROW()=5,0,J14)+IF(G15="-",0,IF(G15="",0,G15))) | K15: =IF(C15<>"",IF(INDEX(仕訳帳!F:F,MATCH(C15,仕訳帳!B:B,0))="","",INDEX(仕訳帳!F:F,MATCH(C15,仕訳帳!B:B,0))),"") | L15: =IF(C15<>"",IF(INDEX(仕訳帳!K:K,MATCH(C15,仕訳帳!B:B,0))="","",INDEX(仕訳帳!K:K,MATCH(C15,仕訳帳!B:B,0))),"")
B16: =IF(C16<>"",INDEX(仕訳帳!C:C,MATCH(C16,仕訳帳!B:B,0)),"") | C16: {=IF($D$2="","",IFERROR(INDEX(仕訳帳!B:B,MATCH(SMALL(IF((仕訳帳!I:I=$D$2)+(仕訳帳!J:J=$D$2),仕訳帳!C:C*10000+ROW(仕訳帳!C:C)),ROW(A12)),仕訳帳!C:C*10000+ROW(仕訳帳!C:C),0)),""))} | D16: =IF(C16<>"",IF(INDEX(仕訳帳!I:I,MATCH(C16,仕訳帳!B:B,0))=$D$2,"---",INDEX(仕訳帳!I:I,MATCH(C16,仕訳帳!B:B,0))),"") | E16: =IF(C16<>"",IF(INDEX(仕訳帳!I:I,MATCH(C16,仕訳帳!B:B,0))=$D$2,"-",INDEX(仕訳帳!E:E,MATCH(C16,仕訳帳!B:B,0))),"") | F16: =IF(C16<>"",IF(INDEX(仕訳帳!J:J,MATCH(C16,仕訳帳!B:B,0))=$D$2,"---",INDEX(仕訳帳!J:J,MATCH(C16,仕訳帳!B:B,0))),"") | G16: =IF(C16<>"",IF(INDEX(仕訳帳!J:J,MATCH(C16,仕訳帳!B:B,0))=$D$2,"-",INDEX(仕訳帳!H:H,MATCH(C16,仕訳帳!B:B,0))),"") | H16: =IF(B16="","",SUM(H15,IF(E16="-",0,-E16)+IF(G16="-",0,G16))) | I16: =IF(C16="","",IF(ROW()=5,0,I15)+IF(E16="-",0,IF(E16="",0,E16))) | J16: =IF(C16="","",IF(ROW()=5,0,J15)+IF(G16="-",0,IF(G16="",0,G16))) | K16: =IF(C16<>"",IF(INDEX(仕訳帳!F:F,MATCH(C16,仕訳帳!B:B,0))="","",INDEX(仕訳帳!F:F,MATCH(C16,仕訳帳!B:B,0))),"") | L16: =IF(C16<>"",IF(INDEX(仕訳帳!K:K,MATCH(C16,仕訳帳!B:B,0))="","",INDEX(仕訳帳!K:K,MATCH(C16,仕訳帳!B:B,0))),"")
... B62: =IF(C62<>"",INDEX(仕訳帳!C:C,MATCH(C62,仕訳帳!B:B,0)),"") | C62: {=IF($D$2="","",IFERROR(INDEX(仕訳帳!B:B,MATCH(SMALL(IF((仕訳帳!I:I=$D$2)+(仕訳帳!J:J=$D$2),仕訳帳!C:C*10000+ROW(仕訳帳!C:C)),ROW(A58)),仕訳帳!C:C*10000+ROW(仕訳帳!C:C),0)),""))} | D62: =IF(C62<>"",IF(INDEX(仕訳帳!I:I,MATCH(C62,仕訳帳!B:B,0))=$D$2,"---",INDEX(仕訳帳!I:I,MATCH(C62,仕訳帳!B:B,0))),"") | E62: =IF(C62<>"",IF(INDEX(仕訳帳!I:I,MATCH(C62,仕訳帳!B:B,0))=$D$2,"-",INDEX(仕訳帳!E:E,MATCH(C62,仕訳帳!B:B,0))),"") | F62: =IF(C62<>"",IF(INDEX(仕訳帳!J:J,MATCH(C62,仕訳帳!B:B,0))=$D$2,"---",INDEX(仕訳帳!J:J,MATCH(C62,仕訳帳!B:B,0))),"") | G62: =IF(C62<>"",IF(INDEX(仕訳帳!J:J,MATCH(C62,仕訳帳!B:B,0))=$D$2,"-",INDEX(仕訳帳!H:H,MATCH(C62,仕訳帳!B:B,0))),"") | H62: =IF(B62="","",SUM(H61,IF(E62="-",0,-E62)+IF(G62="-",0,G62))) | I62: =IF(C62="","",IF(ROW()=5,0,I61)+IF(E62="-",0,IF(E62="",0,E62))) | J62: =IF(C62="","",IF(ROW()=5,0,J61)+IF(G62="-",0,IF(G62="",0,G62))) | K62: =IF(C62<>"",IF(INDEX(仕訳帳!F:F,MATCH(C62,仕訳帳!B:B,0))="","",INDEX(仕訳帳!F:F,MATCH(C62,仕訳帳!B:B,0))),"") | L62: =IF(C62<>"",IF(INDEX(仕訳帳!K:K,MATCH(C62,仕訳帳!B:B,0))="","",INDEX(仕訳帳!K:K,MATCH(C62,仕訳帳!B:B,0))),"")

Sheet 集計確認・分析
B2: コード | C2: 勘定科目 | D2: 分類 | E2: 期首 | F2: 期末
B3: 101 | C3: 現金 | D3: 資産 | E3: =IF(C3="期末商品（製品)棚卸高","-",IF(C3="棚卸資産",SUMPRODUCT((MONTH(仕訳帳!C$4:C$999)=1)*(DAY(仕訳帳!C$4:C$999)=1)*(仕訳帳!I$4:I$999="期首商品（製品)棚卸高")*(仕訳帳!E$4:E$999)),IF(C3="期首商品（製品)棚卸高",SUMPRODUCT((MONTH(仕訳帳!C$4:C$999)=1)*(DAY(仕訳帳!C$4:C$999)=1)*(仕訳帳!I$4:I$999=C3)*(仕訳帳!E$4:E$999)),IF(C3="元入金",-SUMPRODUCT((MONTH(仕訳帳!C$4:C$999)=1)*(DAY(仕訳帳!C$4:C$999)=1)*(仕訳帳!I$4:I$999=C3)*(仕訳帳!E$4:E$999))+SUMPRODUCT((MONTH(仕訳帳!C$4:C$999)=1)*(DAY(仕訳帳!C$4:C$999)=1)*(仕訳帳!J$4:J$999=C3)*(仕訳帳!H$4:H$999)),(IF(OR(D3="負債・資本",D3="収益"),-1,1)*(SUMPRODUCT((MONTH(仕訳帳!C$4:C$999)=1)*(DAY(仕訳帳!C$4:C$999)=1)*(仕訳帳!I$4:I$999=C3)*(仕訳帳!J$4:J$999="元入金")*(仕訳帳!E$4:E$999))-SUMPRODUCT((MONTH(仕訳帳!C$4:C$999)=1)*(DAY(仕訳帳!C$4:C$999)=1)*(仕訳帳!J$4:J$999=C3)*(仕訳帳!I$4:I$999="元入金")*(仕訳帳!H$4:H$999)))))))) -> 0 | F3: =IF(C3="期首商品（製品)棚卸高","-",IF(C3="棚卸資産",SUMPRODUCT((MONTH(仕訳帳!C$4:C$999)=12)*(DAY(仕訳帳!C$4:C$999)=31)*(仕訳帳!J$4:J$999="期末商品（製品)棚卸高")*(仕訳帳!H$4:H$999)),IF(C3="期末商品（製品)棚卸高",SUMPRODUCT((MONTH(仕訳帳!C$4:C$999)=12)*(DAY(仕訳帳!C$4:C$999)=31)*(仕訳帳!J$4:J$999=C3)*(仕訳帳!H$4:H$999)),(IF(OR(D3="負債・資本",D3="収益"),-1,1)*(SUMIF(仕訳帳!I$4:I$999,集計確認・分析!C3,仕訳帳!E$4:E$999)-SUMIF(仕訳帳!J$4:J$999,集計確認・分析!C3,仕訳帳!H$4:H$999)))))) -> 0
B4: 104 | C4: その他の預金 | D4: 資産 | E4: =IF(C4="期末商品（製品)棚卸高","-",IF(C4="棚卸資産",SUMPRODUCT((MONTH(仕訳帳!C$4:C$999)=1)*(DAY(仕訳帳!C$4:C$999)=1)*(仕訳帳!I$4:I$999="期首商品（製品)棚卸高")*(仕訳帳!E$4:E$999)),IF(C4="期首商品（製品)棚卸高",SUMPRODUCT((MONTH(仕訳帳!C$4:C$999)=1)*(DAY(仕訳帳!C$4:C$999)=1)*(仕訳帳!I$4:I$999=C4)*(仕訳帳!E$4:E$999)),IF(C4="元入金",-SUMPRODUCT((MONTH(仕訳帳!C$4:C$999)=1)*(DAY(仕訳帳!C$4:C$999)=1)*(仕訳帳!I$4:I$999=C4)*(仕訳帳!E$4:E$999))+SUMPRODUCT((MONTH(仕訳帳!C$4:C$999)=1)*(DAY(仕訳帳!C$4:C$999)=1)*(仕訳帳!J$4:J$999=C4)*(仕訳帳!H$4:H$999)),(IF(OR(D4="負債・資本",D4="収益"),-1,1)*(SUMPRODUCT((MONTH(仕訳帳!C$4:C$999)=1)*(DAY(仕訳帳!C$4:C$999)=1)*(仕訳帳!I$4:I$999=C4)*(仕訳帳!J$4:J$999="元入金")*(仕訳帳!E$4:E$999))-SUMPRODUCT((MONTH(仕訳帳!C$4:C$999)=1)*(DAY(仕訳帳!C$4:C$999)=1)*(仕訳帳!J$4:J$999=C4)*(仕訳帳!I$4:I$999="元入金")*(仕訳帳!H$4:H$999)))))))) -> 0 | F4: =IF(C4="期首商品（製品)棚卸高","-",IF(C4="棚卸資産",SUMPRODUCT((MONTH(仕訳帳!C$4:C$999)=12)*(DAY(仕訳帳!C$4:C$999)=31)*(仕訳帳!J$4:J$999="期末商品（製品)棚卸高")*(仕訳帳!H$4:H$999)),IF(C4="期末商品（製品)棚卸高",SUMPRODUCT((MONTH(仕訳帳!C$4:C$999)=12)*(DAY(仕訳帳!C$4:C$999)=31)*(仕訳帳!J$4:J$999=C4)*(仕訳帳!H$4:H$999)),(IF(OR(D4="負債・資本",D4="収益"),-1,1)*(SUMIF(仕訳帳!I$4:I$999,集計確認・分析!C4,仕訳帳!E$4:E$999)-SUMIF(仕訳帳!J$4:J$999,集計確認・分析!C4,仕訳帳!H$4:H$999)))))) -> 0
B5: 106 | C5: 売掛金 | D5: 資産 | E5: =IF(C5="期末商品（製品)棚卸高","-",IF(C5="棚卸資産",SUMPRODUCT((MONTH(仕訳帳!C$4:C$999)=1)*(DAY(仕訳帳!C$4:C$999)=1)*(仕訳帳!I$4:I$999="期首商品（製品)棚卸高")*(仕訳帳!E$4:E$999)),IF(C5="期首商品（製品)棚卸高",SUMPRODUCT((MONTH(仕訳帳!C$4:C$999)=1)*(DAY(仕訳帳!C$4:C$999)=1)*(仕訳帳!I$4:I$999=C5)*(仕訳帳!E$4:E$999)),IF(C5="元入金",-SUMPRODUCT((MONTH(仕訳帳!C$4:C$999)=1)*(DAY(仕訳帳!C$4:C$999)=1)*(仕訳帳!I$4:I$999=C5)*(仕訳帳!E$4:E$999))+SUMPRODUCT((MONTH(仕訳帳!C$4:C$999)=1)*(DAY(仕訳帳!C$4:C$999)=1)*(仕訳帳!J$4:J$999=C5)*(仕訳帳!H$4:H$999)),(IF(OR(D5="負債・資本",D5="収益"),-1,1)*(SUMPRODUCT((MONTH(仕訳帳!C$4:C$999)=1)*(DAY(仕訳帳!C$4:C$999)=1)*(仕訳帳!I$4:I$999=C5)*(仕訳帳!J$4:J$999="元入金")*(仕訳帳!E$4:E$999))-SUMPRODUCT((MONTH(仕訳帳!C$4:C$999)=1)*(DAY(仕訳帳!C$4:C$999)=1)*(仕訳帳!J$4:J$999=C5)*(仕訳帳!I$4:I$999="元入金")*(仕訳帳!H$4:H$999)))))))) -> 0 | F5: =IF(C5="期首商品（製品)棚卸高","-",IF(C5="棚卸資産",SUMPRODUCT((MONTH(仕訳帳!C$4:C$999)=12)*(DAY(仕訳帳!C$4:C$999)=31)*(仕訳帳!J$4:J$999="期末商品（製品)棚卸高")*(仕訳帳!H$4:H$999)),IF(C5="期末商品（製品)棚卸高",SUMPRODUCT((MONTH(仕訳帳!C$4:C$999)=12)*(DAY(仕訳帳!C$4:C$999)=31)*(仕訳帳!J$4:J$999=C5)*(仕訳帳!H$4:H$999)),(IF(OR(D5="負債・資本",D5="収益"),-1,1)*(SUMIF(仕訳帳!I$4:I$999,集計確認・分析!C5,仕訳帳!E$4:E$999)-SUMIF(仕訳帳!J$4:J$999,集計確認・分析!C5,仕訳帳!H$4:H$999)))))) -> 0
E6: =IF(C6="期末商品（製品)棚卸高","-",IF(C6="棚卸資産",SUMPRODUCT((MONTH(仕訳帳!C$4:C$999)=1)*(DAY(仕訳帳!C$4:C$999)=1)*(仕訳帳!I$4:I$999="期首商品（製品)棚卸高")*(仕訳帳!E$4:E$999)),IF(C6="期首商品（製品)棚卸高",SUMPRODUCT((MONTH(仕訳帳!C$4:C$999)=1)*(DAY(仕訳帳!C$4:C$999)=1)*(仕訳帳!I$4:I$999=C6)*(仕訳帳!E$4:E$999)),IF(C6="元入金",-SUMPRODUCT((MONTH(仕訳帳!C$4:C$999)=1)*(DAY(仕訳帳!C$4:C$999)=1)*(仕訳帳!I$4:I$999=C6)*(仕訳帳!E$4:E$999))+SUMPRODUCT((MONTH(仕訳帳!C$4:C$999)=1)*(DAY(仕訳帳!C$4:C$999)=1)*(仕訳帳!J$4:J$999=C6)*(仕訳帳!H$4:H$999)),(IF(OR(D6="負債・資本",D6="収益"),-1,1)*(SUMPRODUCT((MONTH(仕訳帳!C$4:C$999)=1)*(DAY(仕訳帳!C$4:C$999)=1)*(仕訳帳!I$4:I$999=C6)*(仕訳帳!J$4:J$999="元入金")*(仕訳帳!E$4:E$999))-SUMPRODUCT((MONTH(仕訳帳!C$4:C$999)=1)*(DAY(仕訳帳!C$4:C$999)=1)*(仕訳帳!J$4:J$999=C6)*(仕訳帳!I$4:I$999="元入金")*(仕訳帳!H$4:H$999)))))))) -> 0 | F6: =IF(C6="期首商品（製品)棚卸高","-",IF(C6="棚卸資産",SUMPRODUCT((MONTH(仕訳帳!C$4:C$999)=12)*(DAY(仕訳帳!C$4:C$999)=31)*(仕訳帳!J$4:J$999="期末商品（製品)棚卸高")*(仕訳帳!H$4:H$999)),IF(C6="期末商品（製品)棚卸高",SUMPRODUCT((MONTH(仕訳帳!C$4:C$999)=12)*(DAY(仕訳帳!C$4:C$999)=31)*(仕訳帳!J$4:J$999=C6)*(仕訳帳!H$4:H$999)),(IF(OR(D6="負債・資本",D6="収益"),-1,1)*(SUMIF(仕訳帳!I$4:I$999,集計確認・分析!C6,仕訳帳!E$4:E$999)-SUMIF(仕訳帳!J$4:J$999,集計確認・分析!C6,仕訳帳!H$4:H$999)))))) -> 0
